Workbook

Sheet Mẫu Thiết lập ban đầu
B1: MẪU BIỂU ĐỒ GANTT | I1: Mẹo sử dụng Smartsheet ➜ | O1: Lịch trình trực quan của biểu đồ Gantt cho phép bạn xem chi tiết mỗi công việc cũng như các phần thuộc về dự án. | AH1: Tham khảo khóa học:
AH2: Khóa học Kỹ năng lập kế hoạch và viết báo cáo tại Học Viện Quản Lý PACE
B3: TIÊU ĐỀ DỰ ÁN | D3: DEMO QUẢN LÝ DỰ ÁN A BẰNG GANTT CHART | I3: TÊN CÔNG TY | P3: Học Viện Quản Lý PACE
B4: NGƯỜI QUẢN LÝ DỰ ÁN | D4: Nguyễn Thành Phú | I4: NGÀY | P4: =TODAY() -> 45909
B5: LIÊN HỆ | D5: https://bit.ly/nguyen-thanh-phu | I5: Xem hướng dẫn chi tiết: Vẽ sơ đồ GANTT CHART
B7: SỐ CẤU TRÚC PHÂN CHIA CÔNG VIỆC (WBS) | C7: TIÊU ĐỀ CÔNG VIỆC | D7: NGƯỜI PHỤ TRÁCH CÔNG VIỆC | E7: NGÀY BẮT ĐẦU | F7: NGÀY ĐẾN HẠN | G7: THỜI GIAN | H7: PHẦN TRĂM CÔNG VIỆC HOÀN THÀNH | I7: GIAI ĐOẠN 1 | X7: GIAI ĐOẠN 2 | AM7: GIAI ĐOẠN 3 | BB7: GIAI ĐOẠN 4
I8: TUẦN 1 | N8: TUẦN 2 | S8: TUẦN 3 | X8: TUẦN 4 | AC8: TUẦN 5 | AH8: TUẦN 6 | AM8: TUẦN 7 | AR8: TUẦN 8 | AW8: TUẦN 9 | BB8: TUẦN 10 | BG8: TUẦN 11 | BL8: TUẦN 12
I9: T2 | J9: T3 | K9: T4 | L9: T5 | M9: T6 | N9: T2 | O9: T3 | P9: T4 | Q9: T5 | R9: T6 | S9: T2 | T9: T3 | U9: T4 | V9: T5 | W9: T6 | X9: T2 | Y9: T3 | Z9: T4 | AA9: T5 | AB9: T6 | AC9: T2 | AD9: T3 | AE9: T4 | AF9: T5 | AG9: T6 | AH9: T2 | AI9: T3 | AJ9: T4 | AK9: T5 | AL9: T6 | AM9: T2 | AN9: T3 | AO9: T4 | AP9: T5 | AQ9: T6 | AR9: T2 | AS9: T3 | AT9: T4 | AU9: T5 | AV9: T6 | AW9: T2 | AX9: T3 | AY9: T4 | AZ9: T5 | BA9: T6 | BB9: T2 | BC9: T3 | BD9: T4 | BE9: T5 | BF9: T6 | BG9: T2 | BH9: T3 | BI9: T4 | BJ9: T5 | BK9: T6 | BL9: T2 | BM9: T3 | BN9: T4 | BO9: T5 | BP9: T6
B10: 1 | C10: Lên ý tưởng và thiết lập dự án
B11: 43101 | C11: Hiến chương dự án | D11: Tên người | E11: =TODAY() -> 45909 | F11: =E11+3 -> 45912 | G11: =DAYS360(E11,F11) -> 3 | H11: 0
B12: 1.1.1 | C12: Bản sửa đổi hiến chương dự án | D12: Tên người | E12: =F11 -> 45912 | F12: =E12+1 -> 45913 | G12: =DAYS360(E12,F12) -> 1 | H12: 0
B13: 43132 | C13: Nghiên cứu | D13: Tên người | E13: =E12 -> 45912 | F13: =E13+6 -> 45918 | G13: =DAYS360(E13,F13) -> 6 | H13: 0
B14: 43160 | C14: Dự toán | D14: Tên người | E14: =E13+1 -> 45913 | F14: =E14+6 -> 45919 | G14: =DAYS360(E14,F14) -> 6 | H14: 0
B15: 43191 | C15: Các bên liên quan | D15: Tên người | E15: =E14+2 -> 45915 | F15: =E15+4 -> 45919 | G15: =DAYS360(E15,F15) -> 4 | H15: 0
B16: 43221 | C16: Nguyên tắc | D16: Tên người | E16: =E15+1 -> 45916 | F16: =E16+3 -> 45919 | G16: =DAYS360(E16,F16) -> 3 | H16: 0
B17: 43252 | C17: Thiết lập dự án | D17: Tên người | E17: =F16+1 -> 45920 | F17: =E17+1 -> 45921 | G17: =DAYS360(E17,F17) -> 1 | H17: 0
B18: 2 | C18: Định nghĩa và hoạch định dự án
B19: 43102 | C19: Đặt ra mục tiêu và phạm vi | D19: Tên người | E19: =F17+1 -> 45922 | F19: =E19+4 -> 45926 | G19: 4 | H19: 0
B20: 43133 | C20: Ngân sách | D20: Tên người | E20: =F19+1 -> 45927 | F20: =E20+3 -> 45930 | G20: 3 | H20: 0
B21: 43161 | C21: Kế hoạch truyền thông | D21: Tên người | E21: ... | F21: ... | G21: 0 | H21: 0
B22: 43192 | C22: Quản lý rủi ro | D22: Tên người | E22: ... | F22: ... | G22: 0 | H22: 0
B23: 3 | C23: Lên ý tưởng và thiết lập dự án
B24: 3.1 | C24: Trạng thái và theo dõi | D24: Tên người | E24: ... | F24: ... | G24: 0 | H24: 0
B25: 3.2 | C25: Chỉ số đo lường hiệu quả công việc (KPI) | D25: Tên người | E25: ... | F25: ... | G25: 0 | H25: 0
B26: 3.2.1 | C26: Giám sát | D26: Tên người | E26: ... | F26: ... | G26: 0 | H26: 0
B27: 3.2.2 | C27: Dự đoán | D27: Tên người | E27: ... | F27: ... | G27: 0 | H27: 0
B28: 3.3 | C28: Bản cập nhật dự án | D28: Tên người | E28: ... | F28: ... | G28: 0 | H28: 0
B29: 3.3.1 | C29: Bản cập nhật biểu đồ | D29: Tên người | E29: ... | F29: ... | G29: 0 | H29: 0
B30: 4 | C30: Hiệu quả của dự án / Giám sát
B31: 43104 | C31: Mục tiêu của dự án | D31: Tên người | E31: ... | F31: ... | G31: 0 | H31: 0
B32: 43135 | C32: Kết quả chuyển giao có chất lượng | D32: Tên người | E32: ... | F32: ... | G32: 0 | H32: 0
B33: 43163 | C33: Theo dõi nỗ lực và chi phí | D33: Tên người | E33: ... | F33: ... | G33: 0 | H33: 0
B34: 43194 | C34: Hiệu quả của dự án | D34: Tên người | E34: ... | F34: ... | G34: 0 | H34: 0
L35: Today
B36: Tham khảo khóa học:
B37: Khóa học Kỹ năng lập kế hoạch và viết báo cáo tại Học Viện Quản Lý PACE

Sheet Mẫu tiến trình chạy
B1: MẪU BIỂU ĐỒ GANTT | I1: Mẹo sử dụng Smartsheet ➜ | O1: Lịch trình trực quan của biểu đồ Gantt cho phép bạn xem chi tiết mỗi công việc cũng như các phần thuộc về dự án.
B3: TIÊU ĐỀ DỰ ÁN | D3: DEMO QUẢN LÝ DỰ ÁN A BẰNG GANTT CHART | I3: TÊN CÔNG TY | P3: Học Viện Quản Lý PACE | AE3: Tham khảo khóa học:
B4: NGƯỜI QUẢN LÝ DỰ ÁN | D4: Nguyễn Thành Phú | I4: NGÀY | P4: =TODAY() -> 45909 | AE4: Khóa học Kỹ năng lập kế hoạch và viết báo cáo tại Học Viện Quản Lý PACE
B5: LIÊN HỆ | D5: https://bit.ly/nguyen-thanh-phu | I5: Xem hướng dẫn chi tiết: Vẽ sơ đồ GANTT CHART
B7: SỐ CẤU TRÚC PHÂN CHIA CÔNG VIỆC (WBS) | C7: TIÊU ĐỀ CÔNG VIỆC | D7: NGƯỜI PHỤ TRÁCH CÔNG VIỆC | E7: NGÀY BẮT ĐẦU | F7: NGÀY ĐẾN HẠN | G7: THỜI GIAN | H7: PHẦN TRĂM CÔNG VIỆC HOÀN THÀNH | I7: GIAI ĐOẠN 1 | X7: GIAI ĐOẠN 2 | AM7: GIAI ĐOẠN 3 | BB7: GIAI ĐOẠN 4
I8: TUẦN 1 | N8: TUẦN 2 | S8: TUẦN 3 | X8: TUẦN 4 | AC8: TUẦN 5 | AH8: TUẦN 6 | AM8: TUẦN 7 | AR8: TUẦN 8 | AW8: TUẦN 9 | BB8: TUẦN 10 | BG8: TUẦN 11 | BL8: TUẦN 12
I9: T2 | J9: T3 | K9: T4 | L9: T5 | M9: T6 | N9: T2 | O9: T3 | P9: T4 | Q9: T5 | R9: T6 | S9: T2 | T9: T3 | U9: T4 | V9: T5 | W9: T6 | X9: T2 | Y9: T3 | Z9: T4 | AA9: T5 | AB9: T6 | AC9: T2 | AD9: T3 | AE9: T4 | AF9: T5 | AG9: T6 | AH9: T2 | AI9: T3 | AJ9: T4 | AK9: T5 | AL9: T6 | AM9: T2 | AN9: T3 | AO9: T4 | AP9: T5 | AQ9: T6 | AR9: T2 | AS9: T3 | AT9: T4 | AU9: T5 | AV9: T6 | AW9: T2 | AX9: T3 | AY9: T4 | AZ9: T5 | BA9: T6 | BB9: T2 | BC9: T3 | BD9: T4 | BE9: T5 | BF9: T6 | BG9: T2 | BH9: T3 | BI9: T4 | BJ9: T5 | BK9: T6 | BL9: T2 | BM9: T3 | BN9: T4 | BO9: T5 | BP9: T6
B10: 1 | C10: Lên ý tưởng và thiết lập dự án
B11: 43101 | C11: Hiến chương dự án | D11: Tên người | E11: =TODAY() -> 45909 | F11: =E11+3 -> 45912 | G11: =DAYS360(E11,F11) -> 3 | H11: 1
B12: 1.1.1 | C12: Bản sửa đổi hiến chương dự án | D12: Tên người | E12: =F11 -> 45912 | F12: =E12+1 -> 45913 | G12: =DAYS360(E12,F12) -> 1 | H12: 1
B13: 43132 | C13: Nghiên cứu | D13: Tên người | E13: =E12 -> 45912 | F13: =E13+6 -> 45918 | G13: =DAYS360(E13,F13) -> 6 | H13: 0.9
B14: 43160 | C14: Dự toán | D14: Tên người | E14: =E13+1 -> 45913 | F14: =E14+6 -> 45919 | G14: =DAYS360(E14,F14) -> 6 | H14: 0.4
B15: 43191 | C15: Các bên liên quan | D15: Tên người | E15: =E14+2 -> 45915 | F15: =E15+4 -> 45919 | G15: =DAYS360(E15,F15) -> 4 | H15: 0.7
B16: 43221 | C16: Nguyên tắc | D16: Tên người | E16: =E15+1 -> 45916 | F16: =E16+3 -> 45919 | G16: =DAYS360(E16,F16) -> 3 | H16: 0.6
B17: 43252 | C17: Thiết lập dự án | D17: Tên người | E17: =F16+1 -> 45920 | F17: =E17+1 -> 45921 | G17: =DAYS360(E17,F17) -> 1 | H17: 0
B18: 2 | C18: Định nghĩa và hoạch định dự án
B19: 43102 | C19: Đặt ra mục tiêu và phạm vi | D19: Tên người | E19: =F17+1 -> 45922 | F19: =E19+4 -> 45926 | G19: 4 | H19: 0.22
B20: 43133 | C20: Ngân sách | D20: Tên người | E20: =F19+1 -> 45927 | F20: =E20+3 -> 45930 | G20: 3 | H20: 0
B21: 43161 | C21: Kế hoạch truyền thông | D21: Tên người | E21: ... | F21: ... | G21: 0 | H21: 0
B22: 43192 | C22: Quản lý rủi ro | D22: Tên người | E22: ... | F22: ... | G22: 0 | H22: 0
B23: 3 | C23: Lên ý tưởng và thiết lập dự án
B24: 3.1 | C24: Trạng thái và theo dõi | D24: Tên người | E24: ... | F24: ... | G24: 0 | H24: 0
B25: 3.2 | C25: Chỉ số đo lường hiệu quả công việc (KPI) | D25: Tên người | E25: ... | F25: ... | G25: 0 | H25: 0
B26: 3.2.1 | C26: Giám sát | D26: Tên người | E26: ... | F26: ... | G26: 0 | H26: 0
B27: 3.2.2 | C27: Dự đoán | D27: Tên người | E27: ... | F27: ... | G27: 0 | H27: 0
B28: 3.3 | C28: Bản cập nhật dự án | D28: Tên người | E28: ... | F28: ... | G28: 0 | H28: 0
B29: 3.3.1 | C29: Bản cập nhật biểu đồ | D29: Tên người | E29: ... | F29: ... | G29: 0 | H29: 0
B30: 4 | C30: Hiệu quả của dự án / Giám sát
B31: 43104 | C31: Mục tiêu của dự án | D31: Tên người | E31: ... | F31: ... | G31: 0 | H31: 0
B32: 43135 | C32: Kết quả chuyển giao có chất lượng | D32: Tên người | E32: ... | F32: ... | G32: 0 | H32: 0
B33: 43163 | C33: Theo dõi nỗ lực và chi phí | D33: Tên người | E33: ... | F33: ... | G33: 0 | H33: 0
B34: 43194 | C34: Hiệu quả của dự án | D34: Tên người | E34: ... | F34: ... | G34: 0 | H34: 0
S35: Today
B36: Tham khảo khóa học:
B37: Khóa học Kỹ năng lập kế hoạch và viết báo cáo tại Học Viện Quản Lý PACE

Sheet Migration
C2: Storage | D2: Unit | E2: Quantity | F2: Price | G2: Total
C3: Salesforce | D3: GB
C4: Archive | D4: GB

Sheet BPM 1 DEV
A1: # | B1: Complete Date | C1: No of DEV | D1: BA+QA Rate | E1: DAY(S) | F1: START DAY | G1: Month 1 | H1: Month 2 | I1: Month 3 | J1: Month 4 | K1: Month 5 | L1: Month 6 | M1: Month 7 | N1: Month 8 | O1: Month 9 | P1: Month 10 | Q1: Month 11 | R1: Month 12 | S1: Month 13 | T1: Month 14 | U1: Month 15 | V1: Month 16 | W1: Month 17 | X1: Month 18 | Y1: Month 19 | Z1: Month 20 | AA1: Month 21 | AB1: Month 22 | AC1: Month 23 | AD1: Month 24 | AE1: Month 25 | AF1: Month 26 | AG1: Month 27 | AH1: Month 28 | AI1: Month 29 | AJ1: Month 30 | AK1: Month 31 | AL1: Month 32 | AM1: Month 33 | AN1: Month 34 | AO1: Month 35 | AP1: Month 23 | AQ1: Month 24 | AR1: Month 25 | AS1: Month 26 | AT1: Month 27 | AU1: Month 28 | AV1: Month 29 | AW1: Month 30 | AX1: Month 31 | AY1: Month 32 | AZ1: Month 33 | BA1: Month 34 | BB1: Month 35
B2: =WORKDAY($F$3,ROUNDUP(($E$3-$E$4)/$C$2,0)+$E$4,Holiday!$A$1:$A$30) -> 47422 | C2: 1 | D2: =Setting!$A$2 -> 0.5
B3: WORK TITLE | C3: PIC | D3: DEV- ESTIMATION | E3: =SUM(E4:E103) -> 996 | F3: =Setting!$B$2 -> 46023 | G3: =WORKDAY(F3,22,Holiday!$A$1:$A$30) -> 46055 | H3: =WORKDAY(G3,22,Holiday!$A$1:$A$30) -> 46085 | I3: =WORKDAY(H3,22,Holiday!$A$1:$A$30) -> 46115 | J3: =WORKDAY(I3,22,Holiday!$A$1:$A$30) -> 46149 | K3: =WORKDAY(J3,22,Holiday!$A$1:$A$30) -> 46181 | L3: =WORKDAY(K3,22,Holiday!$A$1:$A$30) -> 46211 | M3: =WORKDAY(L3,22,Holiday!$A$1:$A$30) -> 46241 | N3: =WORKDAY(M3,22,Holiday!$A$1:$A$30) -> 46274 | ... BB3: =WORKDAY(BA3,22,Holiday!$A$1:$A$30) -> 47506
B4: Enviroment Preparation | C4: DEV 1 | D4: 20 | E4: 20 | F4: =WORKDAY(F3,E4,Holiday!$A$1:$A$30) -> 46051 | G4: =IF(OR(AND($F3<=G$3, $F4 >= G$3), AND($F4<G$3, WORKDAY($F4, 22,Holiday!$A$1:$A$30)>G$3)), 1, 0)+IF(AND((G$3-$B$2)>=0,(G$3-$B$2)<30), 2,0) -> 1 | H4: =IF(OR(AND($F3<=H$3, $F4 >= H$3), AND($F4<H$3, WORKDAY($F4, 22,Holiday!$A$1:$A$30)>H$3)), 1, 0)+IF(AND((H$3-$B$2)>=0,(H$3-$B$2)<30), 2,0) -> 0 | I4: =IF(OR(AND($F3<=I$3, $F4 >= I$3), AND($F4<I$3, WORKDAY($F4, 22,Holiday!$A$1:$A$30)>I$3)), 1, 0)+IF(AND((I$3-$B$2)>=0,(I$3-$B$2)<30), 2,0) -> 0 | J4: =IF(OR(AND($F3<=J$3, $F4 >= J$3), AND($F4<J$3, WORKDAY($F4, 22,Holiday!$A$1:$A$30)>J$3)), 1, 0)+IF(AND((J$3-$B$2)>=0,(J$3-$B$2)<30), 2,0) -> 0 | K4: =IF(OR(AND($F3<=K$3, $F4 >= K$3), AND($F4<K$3, WORKDAY($F4, 22,Holiday!$A$1:$A$30)>K$3)), 1, 0)+IF(AND((K$3-$B$2)>=0,(K$3-$B$2)<30), 2,0) -> 0 | L4: =IF(OR(AND($F3<=L$3, $F4 >= L$3), AND($F4<L$3, WORKDAY($F4, 22,Holiday!$A$1:$A$30)>L$3)), 1, 0)+IF(AND((L$3-$B$2)>=0,(L$3-$B$2)<30), 2,0) -> 0 | M4: =IF(OR(AND($F3<=M$3, $F4 >= M$3), AND($F4<M$3, WORKDAY($F4, 22,Holiday!$A$1:$A$30)>M$3)), 1, 0)+IF(AND((M$3-$B$2)>=0,(M$3-$B$2)<30), 2,0) -> 0 | N4: =IF(OR(AND($F3<=N$3, $F4 >= N$3), AND($F4<N$3, WORKDAY($F4, 22,Holiday!$A$1:$A$30)>N$3)), 1, 0)+IF(AND((N$3-$B$2)>=0,(N$3-$B$2)<30), 2,0) -> 0 | ... BB4: =IF(OR(AND($F3<=BB$3, $F4 >= BB$3), AND($F4<BB$3, WORKDAY($F4, 22,Holiday!$A$1:$A$30)>BB$3)), 1, 0)+IF(AND((BB$3-$B$2)>=0,(BB$3-$B$2)<30), 2,0) -> 0
B5: Contract/ Click to Call | C5: DEV 1 | D5: 10 | E5: =ROUNDUP(D5*(1+$D$2),0) -> 15 | F5: =WORKDAY(F4,E5,Holiday!A1:A30) -> 46072 | G5: =IF(OR(AND($F4<=G$3, $F5 >= G$3), AND($F5<G$3, WORKDAY($F5, 22,Holiday!$A$1:$A$30)>G$3)), 1, 0)+IF(AND((G$3-$B$2)>=0,(G$3-$B$2)<30), 2,0) -> 1 | H5: =IF(OR(AND($F4<=H$3, $F5 >= H$3), AND($F5<H$3, WORKDAY($F5, 22,Holiday!$A$1:$A$30)>H$3)), 1, 0)+IF(AND((H$3-$B$2)>=0,(H$3-$B$2)<30), 2,0) -> 1 | I5: =IF(OR(AND($F4<=I$3, $F5 >= I$3), AND($F5<I$3, WORKDAY($F5, 22,Holiday!$A$1:$A$30)>I$3)), 1, 0)+IF(AND((I$3-$B$2)>=0,(I$3-$B$2)<30), 2,0) -> 0 | J5: =IF(OR(AND($F4<=J$3, $F5 >= J$3), AND($F5<J$3, WORKDAY($F5, 22,Holiday!$A$1:$A$30)>J$3)), 1, 0)+IF(AND((J$3-$B$2)>=0,(J$3-$B$2)<30), 2,0) -> 0 | K5: =IF(OR(AND($F4<=K$3, $F5 >= K$3), AND($F5<K$3, WORKDAY($F5, 22,Holiday!$A$1:$A$30)>K$3)), 1, 0)+IF(AND((K$3-$B$2)>=0,(K$3-$B$2)<30), 2,0) -> 0 | L5: =IF(OR(AND($F4<=L$3, $F5 >= L$3), AND($F5<L$3, WORKDAY($F5, 22,Holiday!$A$1:$A$30)>L$3)), 1, 0)+IF(AND((L$3-$B$2)>=0,(L$3-$B$2)<30), 2,0) -> 0 | M5: =IF(OR(AND($F4<=M$3, $F5 >= M$3), AND($F5<M$3, WORKDAY($F5, 22,Holiday!$A$1:$A$30)>M$3)), 1, 0)+IF(AND((M$3-$B$2)>=0,(M$3-$B$2)<30), 2,0) -> 0 | N5: =IF(OR(AND($F4<=N$3, $F5 >= N$3), AND($F5<N$3, WORKDAY($F5, 22,Holiday!$A$1:$A$30)>N$3)), 1, 0)+IF(AND((N$3-$B$2)>=0,(N$3-$B$2)<30), 2,0) -> 0 | ... BB5: =IF(OR(AND($F4<=BB$3, $F5 >= BB$3), AND($F5<BB$3, WORKDAY($F5, 22,Holiday!$A$1:$A$30)>BB$3)), 1, 0)+IF(AND((BB$3-$B$2)>=0,(BB$3-$B$2)<30), 2,0) -> 0
B6: Admin Tools/ BIX Dashboard | C6: DEV 1 | D6: 10 | E6: =ROUNDUP(D6*(1+$D$2),0) -> 15 | F6: =WORKDAY(F5,E6,Holiday!A2:A31) -> 46093 | G6: =IF(OR(AND($F5<=G$3, $F6 >= G$3), AND($F6<G$3, WORKDAY($F6, 22,Holiday!$A$1:$A$30)>G$3)), 1, 0)+IF(AND((G$3-$B$2)>=0,(G$3-$B$2)<30), 2,0) -> 0 | H6: =IF(OR(AND($F5<=H$3, $F6 >= H$3), AND($F6<H$3, WORKDAY($F6, 22,Holiday!$A$1:$A$30)>H$3)), 1, 0)+IF(AND((H$3-$B$2)>=0,(H$3-$B$2)<30), 2,0) -> 1 | I6: =IF(OR(AND($F5<=I$3, $F6 >= I$3), AND($F6<I$3, WORKDAY($F6, 22,Holiday!$A$1:$A$30)>I$3)), 1, 0)+IF(AND((I$3-$B$2)>=0,(I$3-$B$2)<30), 2,0) -> 1 | J6: =IF(OR(AND($F5<=J$3, $F6 >= J$3), AND($F6<J$3, WORKDAY($F6, 22,Holiday!$A$1:$A$30)>J$3)), 1, 0)+IF(AND((J$3-$B$2)>=0,(J$3-$B$2)<30), 2,0) -> 0 | K6: =IF(OR(AND($F5<=K$3, $F6 >= K$3), AND($F6<K$3, WORKDAY($F6, 22,Holiday!$A$1:$A$30)>K$3)), 1, 0)+IF(AND((K$3-$B$2)>=0,(K$3-$B$2)<30), 2,0) -> 0 | L6: =IF(OR(AND($F5<=L$3, $F6 >= L$3), AND($F6<L$3, WORKDAY($F6, 22,Holiday!$A$1:$A$30)>L$3)), 1, 0)+IF(AND((L$3-$B$2)>=0,(L$3-$B$2)<30), 2,0) -> 0 | M6: =IF(OR(AND($F5<=M$3, $F6 >= M$3), AND($F6<M$3, WORKDAY($F6, 22,Holiday!$A$1:$A$30)>M$3)), 1, 0)+IF(AND((M$3-$B$2)>=0,(M$3-$B$2)<30), 2,0) -> 0 | N6: =IF(OR(AND($F5<=N$3, $F6 >= N$3), AND($F6<N$3, WORKDAY($F6, 22,Holiday!$A$1:$A$30)>N$3)), 1, 0)+IF(AND((N$3-$B$2)>=0,(N$3-$B$2)<30), 2,0) -> 0 | ... BB6: =IF(OR(AND($F5<=BB$3, $F6 >= BB$3), AND($F6<BB$3, WORKDAY($F6, 22,Holiday!$A$1:$A$30)>BB$3)), 1, 0)+IF(AND((BB$3-$B$2)>=0,(BB$3-$B$2)<30), 2,0) -> 0
B7: Admin Tools/ Bulk Actions | C7: DEV 1 | D7: 10 | E7: =ROUNDUP(D7*(1+$D$2),0) -> 15 | F7: =WORKDAY(F6,E7,Holiday!A3:A32) -> 46114 | G7: =IF(OR(AND($F6<=G$3, $F7 >= G$3), AND($F7<G$3, WORKDAY($F7, 22,Holiday!$A$1:$A$30)>G$3)), 1, 0)+IF(AND((G$3-$B$2)>=0,(G$3-$B$2)<30), 2,0) -> 0 | H7: =IF(OR(AND($F6<=H$3, $F7 >= H$3), AND($F7<H$3, WORKDAY($F7, 22,Holiday!$A$1:$A$30)>H$3)), 1, 0)+IF(AND((H$3-$B$2)>=0,(H$3-$B$2)<30), 2,0) -> 0 | I7: =IF(OR(AND($F6<=I$3, $F7 >= I$3), AND($F7<I$3, WORKDAY($F7, 22,Holiday!$A$1:$A$30)>I$3)), 1, 0)+IF(AND((I$3-$B$2)>=0,(I$3-$B$2)<30), 2,0) -> 1 | J7: =IF(OR(AND($F6<=J$3, $F7 >= J$3), AND($F7<J$3, WORKDAY($F7, 22,Holiday!$A$1:$A$30)>J$3)), 1, 0)+IF(AND((J$3-$B$2)>=0,(J$3-$B$2)<30), 2,0) -> 0 | K7: =IF(OR(AND($F6<=K$3, $F7 >= K$3), AND($F7<K$3, WORKDAY($F7, 22,Holiday!$A$1:$A$30)>K$3)), 1, 0)+IF(AND((K$3-$B$2)>=0,(K$3-$B$2)<30), 2,0) -> 0 | L7: =IF(OR(AND($F6<=L$3, $F7 >= L$3), AND($F7<L$3, WORKDAY($F7, 22,Holiday!$A$1:$A$30)>L$3)), 1, 0)+IF(AND((L$3-$B$2)>=0,(L$3-$B$2)<30), 2,0) -> 0 | M7: =IF(OR(AND($F6<=M$3, $F7 >= M$3), AND($F7<M$3, WORKDAY($F7, 22,Holiday!$A$1:$A$30)>M$3)), 1, 0)+IF(AND((M$3-$B$2)>=0,(M$3-$B$2)<30), 2,0) -> 0 | N7: =IF(OR(AND($F6<=N$3, $F7 >= N$3), AND($F7<N$3, WORKDAY($F7, 22,Holiday!$A$1:$A$30)>N$3)), 1, 0)+IF(AND((N$3-$B$2)>=0,(N$3-$B$2)<30), 2,0) -> 0 | ... BB7: =IF(OR(AND($F6<=BB$3, $F7 >= BB$3), AND($F7<BB$3, WORKDAY($F7, 22,Holiday!$A$1:$A$30)>BB$3)), 1, 0)+IF(AND((BB$3-$B$2)>=0,(BB$3-$B$2)<30), 2,0) -> 0
B8: Admin Tools/ Bulk Upload File Processing | C8: DEV 1 | D8: 10 | E8: =ROUNDUP(D8*(1+$D$2),0) -> 15 | F8: =WORKDAY(F7,E8,Holiday!A4:A33) -> 46135 | G8: =IF(OR(AND($F7<=G$3, $F8 >= G$3), AND($F8<G$3, WORKDAY($F8, 22,Holiday!$A$1:$A$30)>G$3)), 1, 0)+IF(AND((G$3-$B$2)>=0,(G$3-$B$2)<30), 2,0) -> 0 | H8: =IF(OR(AND($F7<=H$3, $F8 >= H$3), AND($F8<H$3, WORKDAY($F8, 22,Holiday!$A$1:$A$30)>H$3)), 1, 0)+IF(AND((H$3-$B$2)>=0,(H$3-$B$2)<30), 2,0) -> 0 | I8: =IF(OR(AND($F7<=I$3, $F8 >= I$3), AND($F8<I$3, WORKDAY($F8, 22,Holiday!$A$1:$A$30)>I$3)), 1, 0)+IF(AND((I$3-$B$2)>=0,(I$3-$B$2)<30), 2,0) -> 1 | J8: =IF(OR(AND($F7<=J$3, $F8 >= J$3), AND($F8<J$3, WORKDAY($F8, 22,Holiday!$A$1:$A$30)>J$3)), 1, 0)+IF(AND((J$3-$B$2)>=0,(J$3-$B$2)<30), 2,0) -> 1 | K8: =IF(OR(AND($F7<=K$3, $F8 >= K$3), AND($F8<K$3, WORKDAY($F8, 22,Holiday!$A$1:$A$30)>K$3)), 1, 0)+IF(AND((K$3-$B$2)>=0,(K$3-$B$2)<30), 2,0) -> 0 | L8: =IF(OR(AND($F7<=L$3, $F8 >= L$3), AND($F8<L$3, WORKDAY($F8, 22,Holiday!$A$1:$A$30)>L$3)), 1, 0)+IF(AND((L$3-$B$2)>=0,(L$3-$B$2)<30), 2,0) -> 0 | M8: =IF(OR(AND($F7<=M$3, $F8 >= M$3), AND($F8<M$3, WORKDAY($F8, 22,Holiday!$A$1:$A$30)>M$3)), 1, 0)+IF(AND((M$3-$B$2)>=0,(M$3-$B$2)<30), 2,0) -> 0 | N8: =IF(OR(AND($F7<=N$3, $F8 >= N$3), AND($F8<N$3, WORKDAY($F8, 22,Holiday!$A$1:$A$30)>N$3)), 1, 0)+IF(AND((N$3-$B$2)>=0,(N$3-$B$2)<30), 2,0) -> 0 | ... BB8: =IF(OR(AND($F7<=BB$3, $F8 >= BB$3), AND($F8<BB$3, WORKDAY($F8, 22,Holiday!$A$1:$A$30)>BB$3)), 1, 0)+IF(AND((BB$3-$B$2)>=0,(BB$3-$B$2)<30), 2,0) -> 0
B9: Admin Tools/ My Reportee | C9: DEV 1 | D9: 10 | E9: =ROUNDUP(D9*(1+$D$2),0) -> 15 | F9: =WORKDAY(F8,E9,Holiday!A5:A34) -> 46157 | G9: =IF(OR(AND($F8<=G$3, $F9 >= G$3), AND($F9<G$3, WORKDAY($F9, 22,Holiday!$A$1:$A$30)>G$3)), 1, 0)+IF(AND((G$3-$B$2)>=0,(G$3-$B$2)<30), 2,0) -> 0 | H9: =IF(OR(AND($F8<=H$3, $F9 >= H$3), AND($F9<H$3, WORKDAY($F9, 22,Holiday!$A$1:$A$30)>H$3)), 1, 0)+IF(AND((H$3-$B$2)>=0,(H$3-$B$2)<30), 2,0) -> 0 | I9: =IF(OR(AND($F8<=I$3, $F9 >= I$3), AND($F9<I$3, WORKDAY($F9, 22,Holiday!$A$1:$A$30)>I$3)), 1, 0)+IF(AND((I$3-$B$2)>=0,(I$3-$B$2)<30), 2,0) -> 0 | J9: =IF(OR(AND($F8<=J$3, $F9 >= J$3), AND($F9<J$3, WORKDAY($F9, 22,Holiday!$A$1:$A$30)>J$3)), 1, 0)+IF(AND((J$3-$B$2)>=0,(J$3-$B$2)<30), 2,0) -> 1 | K9: =IF(OR(AND($F8<=K$3, $F9 >= K$3), AND($F9<K$3, WORKDAY($F9, 22,Holiday!$A$1:$A$30)>K$3)), 1, 0)+IF(AND((K$3-$B$2)>=0,(K$3-$B$2)<30), 2,0) -> 1 | L9: =IF(OR(AND($F8<=L$3, $F9 >= L$3), AND($F9<L$3, WORKDAY($F9, 22,Holiday!$A$1:$A$30)>L$3)), 1, 0)+IF(AND((L$3-$B$2)>=0,(L$3-$B$2)<30), 2,0) -> 0 | M9: =IF(OR(AND($F8<=M$3, $F9 >= M$3), AND($F9<M$3, WORKDAY($F9, 22,Holiday!$A$1:$A$30)>M$3)), 1, 0)+IF(AND((M$3-$B$2)>=0,(M$3-$B$2)<30), 2,0) -> 0 | N9: =IF(OR(AND($F8<=N$3, $F9 >= N$3), AND($F9<N$3, WORKDAY($F9, 22,Holiday!$A$1:$A$30)>N$3)), 1, 0)+IF(AND((N$3-$B$2)>=0,(N$3-$B$2)<30), 2,0) -> 0 | ... BB9: =IF(OR(AND($F8<=BB$3, $F9 >= BB$3), AND($F9<BB$3, WORKDAY($F9, 22,Holiday!$A$1:$A$30)>BB$3)), 1, 0)+IF(AND((BB$3-$B$2)>=0,(BB$3-$B$2)<30), 2,0) -> 0
B10: Admin Tools/ Reset QR code Google Authenticator | C10: DEV 1 | D10: 10 | E10: =ROUNDUP(D10*(1+$D$2),0) -> 15 | F10: =WORKDAY(F9,E10,Holiday!A6:A35) -> 46178 | G10: =IF(OR(AND($F9<=G$3, $F10 >= G$3), AND($F10<G$3, WORKDAY($F10, 22,Holiday!$A$1:$A$30)>G$3)), 1, 0)+IF(AND((G$3-$B$2)>=0,(G$3-$B$2)<30), 2,0) -> 0 | H10: =IF(OR(AND($F9<=H$3, $F10 >= H$3), AND($F10<H$3, WORKDAY($F10, 22,Holiday!$A$1:$A$30)>H$3)), 1, 0)+IF(AND((H$3-$B$2)>=0,(H$3-$B$2)<30), 2,0) -> 0 | I10: =IF(OR(AND($F9<=I$3, $F10 >= I$3), AND($F10<I$3, WORKDAY($F10, 22,Holiday!$A$1:$A$30)>I$3)), 1, 0)+IF(AND((I$3-$B$2)>=0,(I$3-$B$2)<30), 2,0) -> 0 | J10: =IF(OR(AND($F9<=J$3, $F10 >= J$3), AND($F10<J$3, WORKDAY($F10, 22,Holiday!$A$1:$A$30)>J$3)), 1, 0)+IF(AND((J$3-$B$2)>=0,(J$3-$B$2)<30), 2,0) -> 0 | K10: =IF(OR(AND($F9<=K$3, $F10 >= K$3), AND($F10<K$3, WORKDAY($F10, 22,Holiday!$A$1:$A$30)>K$3)), 1, 0)+IF(AND((K$3-$B$2)>=0,(K$3-$B$2)<30), 2,0) -> 1 | L10: =IF(OR(AND($F9<=L$3, $F10 >= L$3), AND($F10<L$3, WORKDAY($F10, 22,Holiday!$A$1:$A$30)>L$3)), 1, 0)+IF(AND((L$3-$B$2)>=0,(L$3-$B$2)<30), 2,0) -> 0 | M10: =IF(OR(AND($F9<=M$3, $F10 >= M$3), AND($F10<M$3, WORKDAY($F10, 22,Holiday!$A$1:$A$30)>M$3)), 1, 0)+IF(AND((M$3-$B$2)>=0,(M$3-$B$2)<30), 2,0) -> 0 | N10: =IF(OR(AND($F9<=N$3, $F10 >= N$3), AND($F10<N$3, WORKDAY($F10, 22,Holiday!$A$1:$A$30)>N$3)), 1, 0)+IF(AND((N$3-$B$2)>=0,(N$3-$B$2)<30), 2,0) -> 0 | ... BB10: =IF(OR(AND($F9<=BB$3, $F10 >= BB$3), AND($F10<BB$3, WORKDAY($F10, 22,Holiday!$A$1:$A$30)>BB$3)), 1, 0)+IF(AND((BB$3-$B$2)>=0,(BB$3-$B$2)<30), 2,0) -> 0
B11: Admin Tools/ Sub Pool Distribution | C11: DEV 1 | D11: 10 | E11: =ROUNDUP(D11*(1+$D$2),0) -> 15 | F11: =WORKDAY(F10,E11,Holiday!A7:A36) -> 46199 | G11: =IF(OR(AND($F10<=G$3, $F11 >= G$3), AND($F11<G$3, WORKDAY($F11, 22,Holiday!$A$1:$A$30)>G$3)), 1, 0)+IF(AND((G$3-$B$2)>=0,(G$3-$B$2)<30), 2,0) -> 0 | H11: =IF(OR(AND($F10<=H$3, $F11 >= H$3), AND($F11<H$3, WORKDAY($F11, 22,Holiday!$A$1:$A$30)>H$3)), 1, 0)+IF(AND((H$3-$B$2)>=0,(H$3-$B$2)<30), 2,0) -> 0 | I11: =IF(OR(AND($F10<=I$3, $F11 >= I$3), AND($F11<I$3, WORKDAY($F11, 22,Holiday!$A$1:$A$30)>I$3)), 1, 0)+IF(AND((I$3-$B$2)>=0,(I$3-$B$2)<30), 2,0) -> 0 | J11: =IF(OR(AND($F10<=J$3, $F11 >= J$3), AND($F11<J$3, WORKDAY($F11, 22,Holiday!$A$1:$A$30)>J$3)), 1, 0)+IF(AND((J$3-$B$2)>=0,(J$3-$B$2)<30), 2,0) -> 0 | K11: =IF(OR(AND($F10<=K$3, $F11 >= K$3), AND($F11<K$3, WORKDAY($F11, 22,Holiday!$A$1:$A$30)>K$3)), 1, 0)+IF(AND((K$3-$B$2)>=0,(K$3-$B$2)<30), 2,0) -> 1 | L11: =IF(OR(AND($F10<=L$3, $F11 >= L$3), AND($F11<L$3, WORKDAY($F11, 22,Holiday!$A$1:$A$30)>L$3)), 1, 0)+IF(AND((L$3-$B$2)>=0,(L$3-$B$2)<30), 2,0) -> 1 | M11: =IF(OR(AND($F10<=M$3, $F11 >= M$3), AND($F11<M$3, WORKDAY($F11, 22,Holiday!$A$1:$A$30)>M$3)), 1, 0)+IF(AND((M$3-$B$2)>=0,(M$3-$B$2)<30), 2,0) -> 0 | N11: =IF(OR(AND($F10<=N$3, $F11 >= N$3), AND($F11<N$3, WORKDAY($F11, 22,Holiday!$A$1:$A$30)>N$3)), 1, 0)+IF(AND((N$3-$B$2)>=0,(N$3-$B$2)<30), 2,0) -> 0 | ... BB11: =IF(OR(AND($F10<=BB$3, $F11 >= BB$3), AND($F11<BB$3, WORKDAY($F11, 22,Holiday!$A$1:$A$30)>BB$3)), 1, 0)+IF(AND((BB$3-$B$2)>=0,(BB$3-$B$2)<30), 2,0) -> 0
B12: Admin Tools/ Summary Report View | C12: DEV 1 | D12: 10 | E12: =ROUNDUP(D12*(1+$D$2),0) -> 15 | F12: =WORKDAY(F11,E12,Holiday!A8:A37) -> 46220 | G12: =IF(OR(AND($F11<=G$3, $F12 >= G$3), AND($F12<G$3, WORKDAY($F12, 22,Holiday!$A$1:$A$30)>G$3)), 1, 0)+IF(AND((G$3-$B$2)>=0,(G$3-$B$2)<30), 2,0) -> 0 | H12: =IF(OR(AND($F11<=H$3, $F12 >= H$3), AND($F12<H$3, WORKDAY($F12, 22,Holiday!$A$1:$A$30)>H$3)), 1, 0)+IF(AND((H$3-$B$2)>=0,(H$3-$B$2)<30), 2,0) -> 0 | I12: =IF(OR(AND($F11<=I$3, $F12 >= I$3), AND($F12<I$3, WORKDAY($F12, 22,Holiday!$A$1:$A$30)>I$3)), 1, 0)+IF(AND((I$3-$B$2)>=0,(I$3-$B$2)<30), 2,0) -> 0 | J12: =IF(OR(AND($F11<=J$3, $F12 >= J$3), AND($F12<J$3, WORKDAY($F12, 22,Holiday!$A$1:$A$30)>J$3)), 1, 0)+IF(AND((J$3-$B$2)>=0,(J$3-$B$2)<30), 2,0) -> 0 | K12: =IF(OR(AND($F11<=K$3, $F12 >= K$3), AND($F12<K$3, WORKDAY($F12, 22,Holiday!$A$1:$A$30)>K$3)), 1, 0)+IF(AND((K$3-$B$2)>=0,(K$3-$B$2)<30), 2,0) -> 0 | L12: =IF(OR(AND($F11<=L$3, $F12 >= L$3), AND($F12<L$3, WORKDAY($F12, 22,Holiday!$A$1:$A$30)>L$3)), 1, 0)+IF(AND((L$3-$B$2)>=0,(L$3-$B$2)<30), 2,0) -> 1 | M12: =IF(OR(AND($F11<=M$3, $F12 >= M$3), AND($F12<M$3, WORKDAY($F12, 22,Holiday!$A$1:$A$30)>M$3)), 1, 0)+IF(AND((M$3-$B$2)>=0,(M$3-$B$2)<30), 2,0) -> 1 | N12: =IF(OR(AND($F11<=N$3, $F12 >= N$3), AND($F12<N$3, WORKDAY($F12, 22,Holiday!$A$1:$A$30)>N$3)), 1, 0)+IF(AND((N$3-$B$2)>=0,(N$3-$B$2)<30), 2,0) -> 0 | ... BB12: =IF(OR(AND($F11<=BB$3, $F12 >= BB$3), AND($F12<BB$3, WORKDAY($F12, 22,Holiday!$A$1:$A$30)>BB$3)), 1, 0)+IF(AND((BB$3-$B$2)>=0,(BB$3-$B$2)<30), 2,0) -> 0
B13: Admin Tools/ Unblock user | C13: DEV 1 | D13: 10 | E13: =ROUNDUP(D13*(1+$D$2),0) -> 15 | F13: =WORKDAY(F12,E13,Holiday!A9:A38) -> 46241 | G13: =IF(OR(AND($F12<=G$3, $F13 >= G$3), AND($F13<G$3, WORKDAY($F13, 22,Holiday!$A$1:$A$30)>G$3)), 1, 0)+IF(AND((G$3-$B$2)>=0,(G$3-$B$2)<30), 2,0) -> 0 | H13: =IF(OR(AND($F12<=H$3, $F13 >= H$3), AND($F13<H$3, WORKDAY($F13, 22,Holiday!$A$1:$A$30)>H$3)), 1, 0)+IF(AND((H$3-$B$2)>=0,(H$3-$B$2)<30), 2,0) -> 0 | I13: =IF(OR(AND($F12<=I$3, $F13 >= I$3), AND($F13<I$3, WORKDAY($F13, 22,Holiday!$A$1:$A$30)>I$3)), 1, 0)+IF(AND((I$3-$B$2)>=0,(I$3-$B$2)<30), 2,0) -> 0 | J13: =IF(OR(AND($F12<=J$3, $F13 >= J$3), AND($F13<J$3, WORKDAY($F13, 22,Holiday!$A$1:$A$30)>J$3)), 1, 0)+IF(AND((J$3-$B$2)>=0,(J$3-$B$2)<30), 2,0) -> 0 | K13: =IF(OR(AND($F12<=K$3, $F13 >= K$3), AND($F13<K$3, WORKDAY($F13, 22,Holiday!$A$1:$A$30)>K$3)), 1, 0)+IF(AND((K$3-$B$2)>=0,(K$3-$B$2)<30), 2,0) -> 0 | L13: =IF(OR(AND($F12<=L$3, $F13 >= L$3), AND($F13<L$3, WORKDAY($F13, 22,Holiday!$A$1:$A$30)>L$3)), 1, 0)+IF(AND((L$3-$B$2)>=0,(L$3-$B$2)<30), 2,0) -> 0 | M13: =IF(OR(AND($F12<=M$3, $F13 >= M$3), AND($F13<M$3, WORKDAY($F13, 22,Holiday!$A$1:$A$30)>M$3)), 1, 0)+IF(AND((M$3-$B$2)>=0,(M$3-$B$2)<30), 2,0) -> 1 | N13: =IF(OR(AND($F12<=N$3, $F13 >= N$3), AND($F13<N$3, WORKDAY($F13, 22,Holiday!$A$1:$A$30)>N$3)), 1, 0)+IF(AND((N$3-$B$2)>=0,(N$3-$B$2)<30), 2,0) -> 0 | ... BB13: =IF(OR(AND($F12<=BB$3, $F13 >= BB$3), AND($F13<BB$3, WORKDAY($F13, 22,Holiday!$A$1:$A$30)>BB$3)), 1, 0)+IF(AND((BB$3-$B$2)>=0,(BB$3-$B$2)<30), 2,0) -> 0
B14: Admin Tools/ Verify New Contact | C14: DEV 1 | D14: 10 | E14: =ROUNDUP(D14*(1+$D$2),0) -> 15 | F14: =WORKDAY(F13,E14,Holiday!A10:A39) -> 46262 | G14: =IF(OR(AND($F13<=G$3, $F14 >= G$3), AND($F14<G$3, WORKDAY($F14, 22,Holiday!$A$1:$A$30)>G$3)), 1, 0)+IF(AND((G$3-$B$2)>=0,(G$3-$B$2)<30), 2,0) -> 0 | H14: =IF(OR(AND($F13<=H$3, $F14 >= H$3), AND($F14<H$3, WORKDAY($F14, 22,Holiday!$A$1:$A$30)>H$3)), 1, 0)+IF(AND((H$3-$B$2)>=0,(H$3-$B$2)<30), 2,0) -> 0 | I14: =IF(OR(AND($F13<=I$3, $F14 >= I$3), AND($F14<I$3, WORKDAY($F14, 22,Holiday!$A$1:$A$30)>I$3)), 1, 0)+IF(AND((I$3-$B$2)>=0,(I$3-$B$2)<30), 2,0) -> 0 | J14: =IF(OR(AND($F13<=J$3, $F14 >= J$3), AND($F14<J$3, WORKDAY($F14, 22,Holiday!$A$1:$A$30)>J$3)), 1, 0)+IF(AND((J$3-$B$2)>=0,(J$3-$B$2)<30), 2,0) -> 0 | K14: =IF(OR(AND($F13<=K$3, $F14 >= K$3), AND($F14<K$3, WORKDAY($F14, 22,Holiday!$A$1:$A$30)>K$3)), 1, 0)+IF(AND((K$3-$B$2)>=0,(K$3-$B$2)<30), 2,0) -> 0 | L14: =IF(OR(AND($F13<=L$3, $F14 >= L$3), AND($F14<L$3, WORKDAY($F14, 22,Holiday!$A$1:$A$30)>L$3)), 1, 0)+IF(AND((L$3-$B$2)>=0,(L$3-$B$2)<30), 2,0) -> 0 | M14: =IF(OR(AND($F13<=M$3, $F14 >= M$3), AND($F14<M$3, WORKDAY($F14, 22,Holiday!$A$1:$A$30)>M$3)), 1, 0)+IF(AND((M$3-$B$2)>=0,(M$3-$B$2)<30), 2,0) -> 1 | N14: =IF(OR(AND($F13<=N$3, $F14 >= N$3), AND($F14<N$3, WORKDAY($F14, 22,Holiday!$A$1:$A$30)>N$3)), 1, 0)+IF(AND((N$3-$B$2)>=0,(N$3-$B$2)<30), 2,0) -> 1 | ... BB14: =IF(OR(AND($F13<=BB$3, $F14 >= BB$3), AND($F14<BB$3, WORKDAY($F14, 22,Holiday!$A$1:$A$30)>BB$3)), 1, 0)+IF(AND((BB$3-$B$2)>=0,(BB$3-$B$2)<30), 2,0) -> 0
B15: Admin Tools/ Verify Phone List | C15: DEV 1 | D15: 10 | E15: =ROUNDUP(D15*(1+$D$2),0) -> 15 | F15: =WORKDAY(F14,E15,Holiday!A11:A40) -> 46283 | G15: =IF(OR(AND($F14<=G$3, $F15 >= G$3), AND($F15<G$3, WORKDAY($F15, 22,Holiday!$A$1:$A$30)>G$3)), 1, 0)+IF(AND((G$3-$B$2)>=0,(G$3-$B$2)<30), 2,0) -> 0 | H15: =IF(OR(AND($F14<=H$3, $F15 >= H$3), AND($F15<H$3, WORKDAY($F15, 22,Holiday!$A$1:$A$30)>H$3)), 1, 0)+IF(AND((H$3-$B$2)>=0,(H$3-$B$2)<30), 2,0) -> 0 | I15: =IF(OR(AND($F14<=I$3, $F15 >= I$3), AND($F15<I$3, WORKDAY($F15, 22,Holiday!$A$1:$A$30)>I$3)), 1, 0)+IF(AND((I$3-$B$2)>=0,(I$3-$B$2)<30), 2,0) -> 0 | J15: =IF(OR(AND($F14<=J$3, $F15 >= J$3), AND($F15<J$3, WORKDAY($F15, 22,Holiday!$A$1:$A$30)>J$3)), 1, 0)+IF(AND((J$3-$B$2)>=0,(J$3-$B$2)<30), 2,0) -> 0 | K15: =IF(OR(AND($F14<=K$3, $F15 >= K$3), AND($F15<K$3, WORKDAY($F15, 22,Holiday!$A$1:$A$30)>K$3)), 1, 0)+IF(AND((K$3-$B$2)>=0,(K$3-$B$2)<30), 2,0) -> 0 | L15: =IF(OR(AND($F14<=L$3, $F15 >= L$3), AND($F15<L$3, WORKDAY($F15, 22,Holiday!$A$1:$A$30)>L$3)), 1, 0)+IF(AND((L$3-$B$2)>=0,(L$3-$B$2)<30), 2,0) -> 0 | M15: =IF(OR(AND($F14<=M$3, $F15 >= M$3), AND($F15<M$3, WORKDAY($F15, 22,Holiday!$A$1:$A$30)>M$3)), 1, 0)+IF(AND((M$3-$B$2)>=0,(M$3-$B$2)<30), 2,0) -> 0 | N15: =IF(OR(AND($F14<=N$3, $F15 >= N$3), AND($F15<N$3, WORKDAY($F15, 22,Holiday!$A$1:$A$30)>N$3)), 1, 0)+IF(AND((N$3-$B$2)>=0,(N$3-$B$2)<30), 2,0) -> 1 | ... BB15: =IF(OR(AND($F14<=BB$3, $F15 >= BB$3), AND($F15<BB$3, WORKDAY($F15, 22,Holiday!$A$1:$A$30)>BB$3)), 1, 0)+IF(AND((BB$3-$B$2)>=0,(BB$3-$B$2)<30), 2,0) -> 0
B16: Admin Tools/Invalidate Follow-up trail | C16: DEV 1 | D16: 10 | E16: =ROUNDUP(D16*(1+$D$2),0) -> 15 | F16: =WORKDAY(F15,E16,Holiday!A12:A41) -> 46304 | G16: =IF(OR(AND($F15<=G$3, $F16 >= G$3), AND($F16<G$3, WORKDAY($F16, 22,Holiday!$A$1:$A$30)>G$3)), 1, 0)+IF(AND((G$3-$B$2)>=0,(G$3-$B$2)<30), 2,0) -> 0 | H16: =IF(OR(AND($F15<=H$3, $F16 >= H$3), AND($F16<H$3, WORKDAY($F16, 22,Holiday!$A$1:$A$30)>H$3)), 1, 0)+IF(AND((H$3-$B$2)>=0,(H$3-$B$2)<30), 2,0) -> 0 | I16: =IF(OR(AND($F15<=I$3, $F16 >= I$3), AND($F16<I$3, WORKDAY($F16, 22,Holiday!$A$1:$A$30)>I$3)), 1, 0)+IF(AND((I$3-$B$2)>=0,(I$3-$B$2)<30), 2,0) -> 0 | J16: =IF(OR(AND($F15<=J$3, $F16 >= J$3), AND($F16<J$3, WORKDAY($F16, 22,Holiday!$A$1:$A$30)>J$3)), 1, 0)+IF(AND((J$3-$B$2)>=0,(J$3-$B$2)<30), 2,0) -> 0 | K16: =IF(OR(AND($F15<=K$3, $F16 >= K$3), AND($F16<K$3, WORKDAY($F16, 22,Holiday!$A$1:$A$30)>K$3)), 1, 0)+IF(AND((K$3-$B$2)>=0,(K$3-$B$2)<30), 2,0) -> 0 | L16: =IF(OR(AND($F15<=L$3, $F16 >= L$3), AND($F16<L$3, WORKDAY($F16, 22,Holiday!$A$1:$A$30)>L$3)), 1, 0)+IF(AND((L$3-$B$2)>=0,(L$3-$B$2)<30), 2,0) -> 0 | M16: =IF(OR(AND($F15<=M$3, $F16 >= M$3), AND($F16<M$3, WORKDAY($F16, 22,Holiday!$A$1:$A$30)>M$3)), 1, 0)+IF(AND((M$3-$B$2)>=0,(M$3-$B$2)<30), 2,0) -> 0 | N16: =IF(OR(AND($F15<=N$3, $F16 >= N$3), AND($F16<N$3, WORKDAY($F16, 22,Holiday!$A$1:$A$30)>N$3)), 1, 0)+IF(AND((N$3-$B$2)>=0,(N$3-$B$2)<30), 2,0) -> 0 | ... BB16: =IF(OR(AND($F15<=BB$3, $F16 >= BB$3), AND($F16<BB$3, WORKDAY($F16, 22,Holiday!$A$1:$A$30)>BB$3)), 1, 0)+IF(AND((BB$3-$B$2)>=0,(BB$3-$B$2)<30), 2,0) -> 0
... B103: NFU Marked Contracts | C103: DEV 1 | D103: 10 | E103: =ROUNDUP(D103*(1+$D$2),0) -> 15 | F103: =WORKDAY(F102,E103,Holiday!A99:A128) -> 47420 | G103: =IF(OR(AND($F102<=G$3, $F103 >= G$3), AND($F103<G$3, WORKDAY($F103, 22,Holiday!$A$1:$A$30)>G$3)), 1, 0)+IF(AND((G$3-$B$2)>=0,(G$3-$B$2)<30), 2,0) -> 0 | H103: =IF(OR(AND($F102<=H$3, $F103 >= H$3), AND($F103<H$3, WORKDAY($F103, 22,Holiday!$A$1:$A$30)>H$3)), 1, 0)+IF(AND((H$3-$B$2)>=0,(H$3-$B$2)<30), 2,0) -> 0 | I103: =IF(OR(AND($F102<=I$3, $F103 >= I$3), AND($F103<I$3, WORKDAY($F103, 22,Holiday!$A$1:$A$30)>I$3)), 1, 0)+IF(AND((I$3-$B$2)>=0,(I$3-$B$2)<30), 2,0) -> 0 | J103: =IF(OR(AND($F102<=J$3, $F103 >= J$3), AND($F103<J$3, WORKDAY($F103, 22,Holiday!$A$1:$A$30)>J$3)), 1, 0)+IF(AND((J$3-$B$2)>=0,(J$3-$B$2)<30), 2,0) -> 0 | K103: =IF(OR(AND($F102<=K$3, $F103 >= K$3), AND($F103<K$3, WORKDAY($F103, 22,Holiday!$A$1:$A$30)>K$3)), 1, 0)+IF(AND((K$3-$B$2)>=0,(K$3-$B$2)<30), 2,0) -> 0 | L103: =IF(OR(AND($F102<=L$3, $F103 >= L$3), AND($F103<L$3, WORKDAY($F103, 22,Holiday!$A$1:$A$30)>L$3)), 1, 0)+IF(AND((L$3-$B$2)>=0,(L$3-$B$2)<30), 2,0) -> 0 | M103: =IF(OR(AND($F102<=M$3, $F103 >= M$3), AND($F103<M$3, WORKDAY($F103, 22,Holiday!$A$1:$A$30)>M$3)), 1, 0)+IF(AND((M$3-$B$2)>=0,(M$3-$B$2)<30), 2,0) -> 0 | N103: =IF(OR(AND($F102<=N$3, $F103 >= N$3), AND($F103<N$3, WORKDAY($F103, 22,Holiday!$A$1:$A$30)>N$3)), 1, 0)+IF(AND((N$3-$B$2)>=0,(N$3-$B$2)<30), 2,0) -> 0 | ... BB103: =IF(OR(AND($F102<=BB$3, $F103 >= BB$3), AND($F103<BB$3, WORKDAY($F103, 22,Holiday!$A$1:$A$30)>BB$3)), 1, 0)+IF(AND((BB$3-$B$2)>=0,(BB$3-$B$2)<30), 2,0) -> 0

Sheet BPM 2 DEV
A1: # | B1: Complete Date | C1: No of DEV | D1: BA+QA Rate | E1: DAY(S) | F1: START DAY | G1: Month 1 | H1: Month 2 | I1: Month 3 | J1: Month 4 | K1: Month 5 | L1: Month 6 | M1: Month 7 | N1: Month 8 | O1: Month 9 | P1: Month 10 | Q1: Month 11 | R1: Month 12 | S1: Month 13 | T1: Month 14 | U1: Month 15 | V1: Month 16 | W1: Month 17 | X1: Month 18 | Y1: Month 19 | Z1: Month 20 | AA1: Month 21 | AB1: Month 22 | AC1: Month 23 | AD1: Month 24 | AE1: Month 25 | AF1: Month 26 | AG1: Month 27 | AH1: Month 28 | AI1: Month 29 | AJ1: Month 30 | AK1: Month 31 | AL1: Month 32 | AM1: Month 33 | AN1: Month 34 | AO1: Month 35
B2: =WORKDAY($F$3,ROUNDUP(($E$3-$E$4)/$C$2,0)+$E$4,Holiday!$A$1:$A$30) -> 46738 | C2: 2 | D2: =Setting!$A$2 -> 0.5
B3: WORK TITLE | C3: PIC | D3: DEV- ESTIMATION | E3: =SUM(E4:E103) -> 996 | F3: =Setting!$B$2 -> 46023 | G3: =WORKDAY(F3,22,Holiday!$A$1:$A$30) -> 46055 | H3: =WORKDAY(G3,22,Holiday!$A$1:$A$30) -> 46085 | I3: =WORKDAY(H3,22,Holiday!$A$1:$A$30) -> 46115 | J3: =WORKDAY(I3,22,Holiday!$A$1:$A$30) -> 46149 | K3: =WORKDAY(J3,22,Holiday!$A$1:$A$30) -> 46181 | L3: =WORKDAY(K3,22,Holiday!$A$1:$A$30) -> 46211 | M3: =WORKDAY(L3,22,Holiday!$A$1:$A$30) -> 46241 | N3: =WORKDAY(M3,22,Holiday!$A$1:$A$30) -> 46274 | ... AO3: =WORKDAY(AN3,22,Holiday!$A$1:$A$30) -> 47106
B4: Enviroment Preparation | C4: DEVs | D4: 20 | E4: 20 | F4: =WORKDAY(F3,E4,Holiday!$A$1:$A$30) -> 46051 | G4: =IF(OR(AND($F3<=G$3, $F4 >= G$3), AND($F4<G$3, WORKDAY($F4, 22,Holiday!$A$1:$A$30)>G$3)), 1, 0)+IF(AND((G$3-$B$2)>=0,(G$3-$B$2)<30), 2,0) -> 1 | H4: =IF(OR(AND($F3<=H$3, $F4 >= H$3), AND($F4<H$3, WORKDAY($F4, 22,Holiday!$A$1:$A$30)>H$3)), 1, 0)+IF(AND((H$3-$B$2)>=0,(H$3-$B$2)<30), 2,0) -> 0 | I4: =IF(OR(AND($F3<=I$3, $F4 >= I$3), AND($F4<I$3, WORKDAY($F4, 22,Holiday!$A$1:$A$30)>I$3)), 1, 0)+IF(AND((I$3-$B$2)>=0,(I$3-$B$2)<30), 2,0) -> 0 | J4: =IF(OR(AND($F3<=J$3, $F4 >= J$3), AND($F4<J$3, WORKDAY($F4, 22,Holiday!$A$1:$A$30)>J$3)), 1, 0)+IF(AND((J$3-$B$2)>=0,(J$3-$B$2)<30), 2,0) -> 0 | K4: =IF(OR(AND($F3<=K$3, $F4 >= K$3), AND($F4<K$3, WORKDAY($F4, 22,Holiday!$A$1:$A$30)>K$3)), 1, 0)+IF(AND((K$3-$B$2)>=0,(K$3-$B$2)<30), 2,0) -> 0 | L4: =IF(OR(AND($F3<=L$3, $F4 >= L$3), AND($F4<L$3, WORKDAY($F4, 22,Holiday!$A$1:$A$30)>L$3)), 1, 0)+IF(AND((L$3-$B$2)>=0,(L$3-$B$2)<30), 2,0) -> 0 | M4: =IF(OR(AND($F3<=M$3, $F4 >= M$3), AND($F4<M$3, WORKDAY($F4, 22,Holiday!$A$1:$A$30)>M$3)), 1, 0)+IF(AND((M$3-$B$2)>=0,(M$3-$B$2)<30), 2,0) -> 0 | N4: =IF(OR(AND($F3<=N$3, $F4 >= N$3), AND($F4<N$3, WORKDAY($F4, 22,Holiday!$A$1:$A$30)>N$3)), 1, 0)+IF(AND((N$3-$B$2)>=0,(N$3-$B$2)<30), 2,0) -> 0 | ... AO4: =IF(OR(AND($F3<=AO$3, $F4 >= AO$3), AND($F4<AO$3, WORKDAY($F4, 22,Holiday!$A$1:$A$30)>AO$3)), 1, 0)+IF(AND((AO$3-$B$2)>=0,(AO$3-$B$2)<30), 2,0) -> 0
B5: Contract/ Click to Call | C5: DEV 1 | D5: 10 | E5: =ROUNDUP(D5*(1+$D$2),0) -> 15 | F5: =WORKDAY(F4,E5,Holiday!A1:A30) -> 46072 | G5: =IF(OR(AND($F4<=G$3, $F5 >= G$3), AND($F5<G$3, WORKDAY($F5, 22,Holiday!$A$1:$A$30)>G$3)), 1, 0)+IF(AND((G$3-$B$2)>=0,(G$3-$B$2)<30), 2,0) -> 1 | H5: =IF(OR(AND($F4<=H$3, $F5 >= H$3), AND($F5<H$3, WORKDAY($F5, 22,Holiday!$A$1:$A$30)>H$3)), 1, 0)+IF(AND((H$3-$B$2)>=0,(H$3-$B$2)<30), 2,0) -> 1 | I5: =IF(OR(AND($F4<=I$3, $F5 >= I$3), AND($F5<I$3, WORKDAY($F5, 22,Holiday!$A$1:$A$30)>I$3)), 1, 0)+IF(AND((I$3-$B$2)>=0,(I$3-$B$2)<30), 2,0) -> 0 | J5: =IF(OR(AND($F4<=J$3, $F5 >= J$3), AND($F5<J$3, WORKDAY($F5, 22,Holiday!$A$1:$A$30)>J$3)), 1, 0)+IF(AND((J$3-$B$2)>=0,(J$3-$B$2)<30), 2,0) -> 0 | K5: =IF(OR(AND($F4<=K$3, $F5 >= K$3), AND($F5<K$3, WORKDAY($F5, 22,Holiday!$A$1:$A$30)>K$3)), 1, 0)+IF(AND((K$3-$B$2)>=0,(K$3-$B$2)<30), 2,0) -> 0 | L5: =IF(OR(AND($F4<=L$3, $F5 >= L$3), AND($F5<L$3, WORKDAY($F5, 22,Holiday!$A$1:$A$30)>L$3)), 1, 0)+IF(AND((L$3-$B$2)>=0,(L$3-$B$2)<30), 2,0) -> 0 | M5: =IF(OR(AND($F4<=M$3, $F5 >= M$3), AND($F5<M$3, WORKDAY($F5, 22,Holiday!$A$1:$A$30)>M$3)), 1, 0)+IF(AND((M$3-$B$2)>=0,(M$3-$B$2)<30), 2,0) -> 0 | N5: =IF(OR(AND($F4<=N$3, $F5 >= N$3), AND($F5<N$3, WORKDAY($F5, 22,Holiday!$A$1:$A$30)>N$3)), 1, 0)+IF(AND((N$3-$B$2)>=0,(N$3-$B$2)<30), 2,0) -> 0 | ... AO5: =IF(OR(AND($F4<=AO$3, $F5 >= AO$3), AND($F5<AO$3, WORKDAY($F5, 22,Holiday!$A$1:$A$30)>AO$3)), 1, 0)+IF(AND((AO$3-$B$2)>=0,(AO$3-$B$2)<30), 2,0) -> 0
B6: Admin Tools/ BIX Dashboard | C6: DEV 1 | D6: 10 | E6: =ROUNDUP(D6*(1+$D$2),0) -> 15 | F6: =WORKDAY(F5,E6,Holiday!A2:A31) -> 46093 | G6: =IF(OR(AND($F5<=G$3, $F6 >= G$3), AND($F6<G$3, WORKDAY($F6, 22,Holiday!$A$1:$A$30)>G$3)), 1, 0)+IF(AND((G$3-$B$2)>=0,(G$3-$B$2)<30), 2,0) -> 0 | H6: =IF(OR(AND($F5<=H$3, $F6 >= H$3), AND($F6<H$3, WORKDAY($F6, 22,Holiday!$A$1:$A$30)>H$3)), 1, 0)+IF(AND((H$3-$B$2)>=0,(H$3-$B$2)<30), 2,0) -> 1 | I6: =IF(OR(AND($F5<=I$3, $F6 >= I$3), AND($F6<I$3, WORKDAY($F6, 22,Holiday!$A$1:$A$30)>I$3)), 1, 0)+IF(AND((I$3-$B$2)>=0,(I$3-$B$2)<30), 2,0) -> 1 | J6: =IF(OR(AND($F5<=J$3, $F6 >= J$3), AND($F6<J$3, WORKDAY($F6, 22,Holiday!$A$1:$A$30)>J$3)), 1, 0)+IF(AND((J$3-$B$2)>=0,(J$3-$B$2)<30), 2,0) -> 0 | K6: =IF(OR(AND($F5<=K$3, $F6 >= K$3), AND($F6<K$3, WORKDAY($F6, 22,Holiday!$A$1:$A$30)>K$3)), 1, 0)+IF(AND((K$3-$B$2)>=0,(K$3-$B$2)<30), 2,0) -> 0 | L6: =IF(OR(AND($F5<=L$3, $F6 >= L$3), AND($F6<L$3, WORKDAY($F6, 22,Holiday!$A$1:$A$30)>L$3)), 1, 0)+IF(AND((L$3-$B$2)>=0,(L$3-$B$2)<30), 2,0) -> 0 | M6: =IF(OR(AND($F5<=M$3, $F6 >= M$3), AND($F6<M$3, WORKDAY($F6, 22,Holiday!$A$1:$A$30)>M$3)), 1, 0)+IF(AND((M$3-$B$2)>=0,(M$3-$B$2)<30), 2,0) -> 0 | N6: =IF(OR(AND($F5<=N$3, $F6 >= N$3), AND($F6<N$3, WORKDAY($F6, 22,Holiday!$A$1:$A$30)>N$3)), 1, 0)+IF(AND((N$3-$B$2)>=0,(N$3-$B$2)<30), 2,0) -> 0 | ... AO6: =IF(OR(AND($F5<=AO$3, $F6 >= AO$3), AND($F6<AO$3, WORKDAY($F6, 22,Holiday!$A$1:$A$30)>AO$3)), 1, 0)+IF(AND((AO$3-$B$2)>=0,(AO$3-$B$2)<30), 2,0) -> 0
B7: Admin Tools/ Bulk Actions | C7: DEV 1 | D7: 10 | E7: =ROUNDUP(D7*(1+$D$2),0) -> 15 | F7: =WORKDAY(F6,E7,Holiday!A3:A32) -> 46114 | G7: =IF(OR(AND($F6<=G$3, $F7 >= G$3), AND($F7<G$3, WORKDAY($F7, 22,Holiday!$A$1:$A$30)>G$3)), 1, 0)+IF(AND((G$3-$B$2)>=0,(G$3-$B$2)<30), 2,0) -> 0 | H7: =IF(OR(AND($F6<=H$3, $F7 >= H$3), AND($F7<H$3, WORKDAY($F7, 22,Holiday!$A$1:$A$30)>H$3)), 1, 0)+IF(AND((H$3-$B$2)>=0,(H$3-$B$2)<30), 2,0) -> 0 | I7: =IF(OR(AND($F6<=I$3, $F7 >= I$3), AND($F7<I$3, WORKDAY($F7, 22,Holiday!$A$1:$A$30)>I$3)), 1, 0)+IF(AND((I$3-$B$2)>=0,(I$3-$B$2)<30), 2,0) -> 1 | J7: =IF(OR(AND($F6<=J$3, $F7 >= J$3), AND($F7<J$3, WORKDAY($F7, 22,Holiday!$A$1:$A$30)>J$3)), 1, 0)+IF(AND((J$3-$B$2)>=0,(J$3-$B$2)<30), 2,0) -> 0 | K7: =IF(OR(AND($F6<=K$3, $F7 >= K$3), AND($F7<K$3, WORKDAY($F7, 22,Holiday!$A$1:$A$30)>K$3)), 1, 0)+IF(AND((K$3-$B$2)>=0,(K$3-$B$2)<30), 2,0) -> 0 | L7: =IF(OR(AND($F6<=L$3, $F7 >= L$3), AND($F7<L$3, WORKDAY($F7, 22,Holiday!$A$1:$A$30)>L$3)), 1, 0)+IF(AND((L$3-$B$2)>=0,(L$3-$B$2)<30), 2,0) -> 0 | M7: =IF(OR(AND($F6<=M$3, $F7 >= M$3), AND($F7<M$3, WORKDAY($F7, 22,Holiday!$A$1:$A$30)>M$3)), 1, 0)+IF(AND((M$3-$B$2)>=0,(M$3-$B$2)<30), 2,0) -> 0 | N7: =IF(OR(AND($F6<=N$3, $F7 >= N$3), AND($F7<N$3, WORKDAY($F7, 22,Holiday!$A$1:$A$30)>N$3)), 1, 0)+IF(AND((N$3-$B$2)>=0,(N$3-$B$2)<30), 2,0) -> 0 | ... AO7: =IF(OR(AND($F6<=AO$3, $F7 >= AO$3), AND($F7<AO$3, WORKDAY($F7, 22,Holiday!$A$1:$A$30)>AO$3)), 1, 0)+IF(AND((AO$3-$B$2)>=0,(AO$3-$B$2)<30), 2,0) -> 0
B8: Admin Tools/ Bulk Upload File Processing | C8: DEV 1 | D8: 10 | E8: =ROUNDUP(D8*(1+$D$2),0) -> 15 | F8: =WORKDAY(F7,E8,Holiday!A4:A33) -> 46135 | G8: =IF(OR(AND($F7<=G$3, $F8 >= G$3), AND($F8<G$3, WORKDAY($F8, 22,Holiday!$A$1:$A$30)>G$3)), 1, 0)+IF(AND((G$3-$B$2)>=0,(G$3-$B$2)<30), 2,0) -> 0 | H8: =IF(OR(AND($F7<=H$3, $F8 >= H$3), AND($F8<H$3, WORKDAY($F8, 22,Holiday!$A$1:$A$30)>H$3)), 1, 0)+IF(AND((H$3-$B$2)>=0,(H$3-$B$2)<30), 2,0) -> 0 | I8: =IF(OR(AND($F7<=I$3, $F8 >= I$3), AND($F8<I$3, WORKDAY($F8, 22,Holiday!$A$1:$A$30)>I$3)), 1, 0)+IF(AND((I$3-$B$2)>=0,(I$3-$B$2)<30), 2,0) -> 1 | J8: =IF(OR(AND($F7<=J$3, $F8 >= J$3), AND($F8<J$3, WORKDAY($F8, 22,Holiday!$A$1:$A$30)>J$3)), 1, 0)+IF(AND((J$3-$B$2)>=0,(J$3-$B$2)<30), 2,0) -> 1 | K8: =IF(OR(AND($F7<=K$3, $F8 >= K$3), AND($F8<K$3, WORKDAY($F8, 22,Holiday!$A$1:$A$30)>K$3)), 1, 0)+IF(AND((K$3-$B$2)>=0,(K$3-$B$2)<30), 2,0) -> 0 | L8: =IF(OR(AND($F7<=L$3, $F8 >= L$3), AND($F8<L$3, WORKDAY($F8, 22,Holiday!$A$1:$A$30)>L$3)), 1, 0)+IF(AND((L$3-$B$2)>=0,(L$3-$B$2)<30), 2,0) -> 0 | M8: =IF(OR(AND($F7<=M$3, $F8 >= M$3), AND($F8<M$3, WORKDAY($F8, 22,Holiday!$A$1:$A$30)>M$3)), 1, 0)+IF(AND((M$3-$B$2)>=0,(M$3-$B$2)<30), 2,0) -> 0 | N8: =IF(OR(AND($F7<=N$3, $F8 >= N$3), AND($F8<N$3, WORKDAY($F8, 22,Holiday!$A$1:$A$30)>N$3)), 1, 0)+IF(AND((N$3-$B$2)>=0,(N$3-$B$2)<30), 2,0) -> 0 | ... AO8: =IF(OR(AND($F7<=AO$3, $F8 >= AO$3), AND($F8<AO$3, WORKDAY($F8, 22,Holiday!$A$1:$A$30)>AO$3)), 1, 0)+IF(AND((AO$3-$B$2)>=0,(AO$3-$B$2)<30), 2,0) -> 0
B9: Admin Tools/ My Reportee | C9: DEV 1 | D9: 10 | E9: =ROUNDUP(D9*(1+$D$2),0) -> 15 | F9: =WORKDAY(F8,E9,Holiday!A5:A34) -> 46157 | G9: =IF(OR(AND($F8<=G$3, $F9 >= G$3), AND($F9<G$3, WORKDAY($F9, 22,Holiday!$A$1:$A$30)>G$3)), 1, 0)+IF(AND((G$3-$B$2)>=0,(G$3-$B$2)<30), 2,0) -> 0 | H9: =IF(OR(AND($F8<=H$3, $F9 >= H$3), AND($F9<H$3, WORKDAY($F9, 22,Holiday!$A$1:$A$30)>H$3)), 1, 0)+IF(AND((H$3-$B$2)>=0,(H$3-$B$2)<30), 2,0) -> 0 | I9: =IF(OR(AND($F8<=I$3, $F9 >= I$3), AND($F9<I$3, WORKDAY($F9, 22,Holiday!$A$1:$A$30)>I$3)), 1, 0)+IF(AND((I$3-$B$2)>=0,(I$3-$B$2)<30), 2,0) -> 0 | J9: =IF(OR(AND($F8<=J$3, $F9 >= J$3), AND($F9<J$3, WORKDAY($F9, 22,Holiday!$A$1:$A$30)>J$3)), 1, 0)+IF(AND((J$3-$B$2)>=0,(J$3-$B$2)<30), 2,0) -> 1 | K9: =IF(OR(AND($F8<=K$3, $F9 >= K$3), AND($F9<K$3, WORKDAY($F9, 22,Holiday!$A$1:$A$30)>K$3)), 1, 0)+IF(AND((K$3-$B$2)>=0,(K$3-$B$2)<30), 2,0) -> 1 | L9: =IF(OR(AND($F8<=L$3, $F9 >= L$3), AND($F9<L$3, WORKDAY($F9, 22,Holiday!$A$1:$A$30)>L$3)), 1, 0)+IF(AND((L$3-$B$2)>=0,(L$3-$B$2)<30), 2,0) -> 0 | M9: =IF(OR(AND($F8<=M$3, $F9 >= M$3), AND($F9<M$3, WORKDAY($F9, 22,Holiday!$A$1:$A$30)>M$3)), 1, 0)+IF(AND((M$3-$B$2)>=0,(M$3-$B$2)<30), 2,0) -> 0 | N9: =IF(OR(AND($F8<=N$3, $F9 >= N$3), AND($F9<N$3, WORKDAY($F9, 22,Holiday!$A$1:$A$30)>N$3)), 1, 0)+IF(AND((N$3-$B$2)>=0,(N$3-$B$2)<30), 2,0) -> 0 | ... AO9: =IF(OR(AND($F8<=AO$3, $F9 >= AO$3), AND($F9<AO$3, WORKDAY($F9, 22,Holiday!$A$1:$A$30)>AO$3)), 1, 0)+IF(AND((AO$3-$B$2)>=0,(AO$3-$B$2)<30), 2,0) -> 0
B10: Admin Tools/ Reset QR code Google Authenticator | C10: DEV 1 | D10: 10 | E10: =ROUNDUP(D10*(1+$D$2),0) -> 15 | F10: =WORKDAY(F9,E10,Holiday!A6:A35) -> 46178 | G10: =IF(OR(AND($F9<=G$3, $F10 >= G$3), AND($F10<G$3, WORKDAY($F10, 22,Holiday!$A$1:$A$30)>G$3)), 1, 0)+IF(AND((G$3-$B$2)>=0,(G$3-$B$2)<30), 2,0) -> 0 | H10: =IF(OR(AND($F9<=H$3, $F10 >= H$3), AND($F10<H$3, WORKDAY($F10, 22,Holiday!$A$1:$A$30)>H$3)), 1, 0)+IF(AND((H$3-$B$2)>=0,(H$3-$B$2)<30), 2,0) -> 0 | I10: =IF(OR(AND($F9<=I$3, $F10 >= I$3), AND($F10<I$3, WORKDAY($F10, 22,Holiday!$A$1:$A$30)>I$3)), 1, 0)+IF(AND((I$3-$B$2)>=0,(I$3-$B$2)<30), 2,0) -> 0 | J10: =IF(OR(AND($F9<=J$3, $F10 >= J$3), AND($F10<J$3, WORKDAY($F10, 22,Holiday!$A$1:$A$30)>J$3)), 1, 0)+IF(AND((J$3-$B$2)>=0,(J$3-$B$2)<30), 2,0) -> 0 | K10: =IF(OR(AND($F9<=K$3, $F10 >= K$3), AND($F10<K$3, WORKDAY($F10, 22,Holiday!$A$1:$A$30)>K$3)), 1, 0)+IF(AND((K$3-$B$2)>=0,(K$3-$B$2)<30), 2,0) -> 1 | L10: =IF(OR(AND($F9<=L$3, $F10 >= L$3), AND($F10<L$3, WORKDAY($F10, 22,Holiday!$A$1:$A$30)>L$3)), 1, 0)+IF(AND((L$3-$B$2)>=0,(L$3-$B$2)<30), 2,0) -> 0 | M10: =IF(OR(AND($F9<=M$3, $F10 >= M$3), AND($F10<M$3, WORKDAY($F10, 22,Holiday!$A$1:$A$30)>M$3)), 1, 0)+IF(AND((M$3-$B$2)>=0,(M$3-$B$2)<30), 2,0) -> 0 | N10: =IF(OR(AND($F9<=N$3, $F10 >= N$3), AND($F10<N$3, WORKDAY($F10, 22,Holiday!$A$1:$A$30)>N$3)), 1, 0)+IF(AND((N$3-$B$2)>=0,(N$3-$B$2)<30), 2,0) -> 0 | ... AO10: =IF(OR(AND($F9<=AO$3, $F10 >= AO$3), AND($F10<AO$3, WORKDAY($F10, 22,Holiday!$A$1:$A$30)>AO$3)), 1, 0)+IF(AND((AO$3-$B$2)>=0,(AO$3-$B$2)<30), 2,0) -> 0
B11: Admin Tools/ Sub Pool Distribution | C11: DEV 1 | D11: 10 | E11: =ROUNDUP(D11*(1+$D$2),0) -> 15 | F11: =WORKDAY(F10,E11,Holiday!A7:A36) -> 46199 | G11: =IF(OR(AND($F10<=G$3, $F11 >= G$3), AND($F11<G$3, WORKDAY($F11, 22,Holiday!$A$1:$A$30)>G$3)), 1, 0)+IF(AND((G$3-$B$2)>=0,(G$3-$B$2)<30), 2,0) -> 0 | H11: =IF(OR(AND($F10<=H$3, $F11 >= H$3), AND($F11<H$3, WORKDAY($F11, 22,Holiday!$A$1:$A$30)>H$3)), 1, 0)+IF(AND((H$3-$B$2)>=0,(H$3-$B$2)<30), 2,0) -> 0 | I11: =IF(OR(AND($F10<=I$3, $F11 >= I$3), AND($F11<I$3, WORKDAY($F11, 22,Holiday!$A$1:$A$30)>I$3)), 1, 0)+IF(AND((I$3-$B$2)>=0,(I$3-$B$2)<30), 2,0) -> 0 | J11: =IF(OR(AND($F10<=J$3, $F11 >= J$3), AND($F11<J$3, WORKDAY($F11, 22,Holiday!$A$1:$A$30)>J$3)), 1, 0)+IF(AND((J$3-$B$2)>=0,(J$3-$B$2)<30), 2,0) -> 0 | K11: =IF(OR(AND($F10<=K$3, $F11 >= K$3), AND($F11<K$3, WORKDAY($F11, 22,Holiday!$A$1:$A$30)>K$3)), 1, 0)+IF(AND((K$3-$B$2)>=0,(K$3-$B$2)<30), 2,0) -> 1 | L11: =IF(OR(AND($F10<=L$3, $F11 >= L$3), AND($F11<L$3, WORKDAY($F11, 22,Holiday!$A$1:$A$30)>L$3)), 1, 0)+IF(AND((L$3-$B$2)>=0,(L$3-$B$2)<30), 2,0) -> 1 | M11: =IF(OR(AND($F10<=M$3, $F11 >= M$3), AND($F11<M$3, WORKDAY($F11, 22,Holiday!$A$1:$A$30)>M$3)), 1, 0)+IF(AND((M$3-$B$2)>=0,(M$3-$B$2)<30), 2,0) -> 0 | N11: =IF(OR(AND($F10<=N$3, $F11 >= N$3), AND($F11<N$3, WORKDAY($F11, 22,Holiday!$A$1:$A$30)>N$3)), 1, 0)+IF(AND((N$3-$B$2)>=0,(N$3-$B$2)<30), 2,0) -> 0 | ... AO11: =IF(OR(AND($F10<=AO$3, $F11 >= AO$3), AND($F11<AO$3, WORKDAY($F11, 22,Holiday!$A$1:$A$30)>AO$3)), 1, 0)+IF(AND((AO$3-$B$2)>=0,(AO$3-$B$2)<30), 2,0) -> 0
B12: Admin Tools/ Summary Report View | C12: DEV 1 | D12: 10 | E12: =ROUNDUP(D12*(1+$D$2),0) -> 15 | F12: =WORKDAY(F11,E12,Holiday!A8:A37) -> 46220 | G12: =IF(OR(AND($F11<=G$3, $F12 >= G$3), AND($F12<G$3, WORKDAY($F12, 22,Holiday!$A$1:$A$30)>G$3)), 1, 0)+IF(AND((G$3-$B$2)>=0,(G$3-$B$2)<30), 2,0) -> 0 | H12: =IF(OR(AND($F11<=H$3, $F12 >= H$3), AND($F12<H$3, WORKDAY($F12, 22,Holiday!$A$1:$A$30)>H$3)), 1, 0)+IF(AND((H$3-$B$2)>=0,(H$3-$B$2)<30), 2,0) -> 0 | I12: =IF(OR(AND($F11<=I$3, $F12 >= I$3), AND($F12<I$3, WORKDAY($F12, 22,Holiday!$A$1:$A$30)>I$3)), 1, 0)+IF(AND((I$3-$B$2)>=0,(I$3-$B$2)<30), 2,0) -> 0 | J12: =IF(OR(AND($F11<=J$3, $F12 >= J$3), AND($F12<J$3, WORKDAY($F12, 22,Holiday!$A$1:$A$30)>J$3)), 1, 0)+IF(AND((J$3-$B$2)>=0,(J$3-$B$2)<30), 2,0) -> 0 | K12: =IF(OR(AND($F11<=K$3, $F12 >= K$3), AND($F12<K$3, WORKDAY($F12, 22,Holiday!$A$1:$A$30)>K$3)), 1, 0)+IF(AND((K$3-$B$2)>=0,(K$3-$B$2)<30), 2,0) -> 0 | L12: =IF(OR(AND($F11<=L$3, $F12 >= L$3), AND($F12<L$3, WORKDAY($F12, 22,Holiday!$A$1:$A$30)>L$3)), 1, 0)+IF(AND((L$3-$B$2)>=0,(L$3-$B$2)<30), 2,0) -> 1 | M12: =IF(OR(AND($F11<=M$3, $F12 >= M$3), AND($F12<M$3, WORKDAY($F12, 22,Holiday!$A$1:$A$30)>M$3)), 1, 0)+IF(AND((M$3-$B$2)>=0,(M$3-$B$2)<30), 2,0) -> 1 | N12: =IF(OR(AND($F11<=N$3, $F12 >= N$3), AND($F12<N$3, WORKDAY($F12, 22,Holiday!$A$1:$A$30)>N$3)), 1, 0)+IF(AND((N$3-$B$2)>=0,(N$3-$B$2)<30), 2,0) -> 0 | ... AO12: =IF(OR(AND($F11<=AO$3, $F12 >= AO$3), AND($F12<AO$3, WORKDAY($F12, 22,Holiday!$A$1:$A$30)>AO$3)), 1, 0)+IF(AND((AO$3-$B$2)>=0,(AO$3-$B$2)<30), 2,0) -> 0
B13: Admin Tools/ Unblock user | C13: DEV 1 | D13: 10 | E13: =ROUNDUP(D13*(1+$D$2),0) -> 15 | F13: =WORKDAY(F12,E13,Holiday!A9:A38) -> 46241 | G13: =IF(OR(AND($F12<=G$3, $F13 >= G$3), AND($F13<G$3, WORKDAY($F13, 22,Holiday!$A$1:$A$30)>G$3)), 1, 0)+IF(AND((G$3-$B$2)>=0,(G$3-$B$2)<30), 2,0) -> 0 | H13: =IF(OR(AND($F12<=H$3, $F13 >= H$3), AND($F13<H$3, WORKDAY($F13, 22,Holiday!$A$1:$A$30)>H$3)), 1, 0)+IF(AND((H$3-$B$2)>=0,(H$3-$B$2)<30), 2,0) -> 0 | I13: =IF(OR(AND($F12<=I$3, $F13 >= I$3), AND($F13<I$3, WORKDAY($F13, 22,Holiday!$A$1:$A$30)>I$3)), 1, 0)+IF(AND((I$3-$B$2)>=0,(I$3-$B$2)<30), 2,0) -> 0 | J13: =IF(OR(AND($F12<=J$3, $F13 >= J$3), AND($F13<J$3, WORKDAY($F13, 22,Holiday!$A$1:$A$30)>J$3)), 1, 0)+IF(AND((J$3-$B$2)>=0,(J$3-$B$2)<30), 2,0) -> 0 | K13: =IF(OR(AND($F12<=K$3, $F13 >= K$3), AND($F13<K$3, WORKDAY($F13, 22,Holiday!$A$1:$A$30)>K$3)), 1, 0)+IF(AND((K$3-$B$2)>=0,(K$3-$B$2)<30), 2,0) -> 0 | L13: =IF(OR(AND($F12<=L$3, $F13 >= L$3), AND($F13<L$3, WORKDAY($F13, 22,Holiday!$A$1:$A$30)>L$3)), 1, 0)+IF(AND((L$3-$B$2)>=0,(L$3-$B$2)<30), 2,0) -> 0 | M13: =IF(OR(AND($F12<=M$3, $F13 >= M$3), AND($F13<M$3, WORKDAY($F13, 22,Holiday!$A$1:$A$30)>M$3)), 1, 0)+IF(AND((M$3-$B$2)>=0,(M$3-$B$2)<30), 2,0) -> 1 | N13: =IF(OR(AND($F12<=N$3, $F13 >= N$3), AND($F13<N$3, WORKDAY($F13, 22,Holiday!$A$1:$A$30)>N$3)), 1, 0)+IF(AND((N$3-$B$2)>=0,(N$3-$B$2)<30), 2,0) -> 0 | ... AO13: =IF(OR(AND($F12<=AO$3, $F13 >= AO$3), AND($F13<AO$3, WORKDAY($F13, 22,Holiday!$A$1:$A$30)>AO$3)), 1, 0)+IF(AND((AO$3-$B$2)>=0,(AO$3-$B$2)<30), 2,0) -> 0
B14: Admin Tools/ Verify New Contact | C14: DEV 1 | D14: 10 | E14: =ROUNDUP(D14*(1+$D$2),0) -> 15 | F14: =WORKDAY(F13,E14,Holiday!A10:A39) -> 46262 | G14: =IF(OR(AND($F13<=G$3, $F14 >= G$3), AND($F14<G$3, WORKDAY($F14, 22,Holiday!$A$1:$A$30)>G$3)), 1, 0)+IF(AND((G$3-$B$2)>=0,(G$3-$B$2)<30), 2,0) -> 0 | H14: =IF(OR(AND($F13<=H$3, $F14 >= H$3), AND($F14<H$3, WORKDAY($F14, 22,Holiday!$A$1:$A$30)>H$3)), 1, 0)+IF(AND((H$3-$B$2)>=0,(H$3-$B$2)<30), 2,0) -> 0 | I14: =IF(OR(AND($F13<=I$3, $F14 >= I$3), AND($F14<I$3, WORKDAY($F14, 22,Holiday!$A$1:$A$30)>I$3)), 1, 0)+IF(AND((I$3-$B$2)>=0,(I$3-$B$2)<30), 2,0) -> 0 | J14: =IF(OR(AND($F13<=J$3, $F14 >= J$3), AND($F14<J$3, WORKDAY($F14, 22,Holiday!$A$1:$A$30)>J$3)), 1, 0)+IF(AND((J$3-$B$2)>=0,(J$3-$B$2)<30), 2,0) -> 0 | K14: =IF(OR(AND($F13<=K$3, $F14 >= K$3), AND($F14<K$3, WORKDAY($F14, 22,Holiday!$A$1:$A$30)>K$3)), 1, 0)+IF(AND((K$3-$B$2)>=0,(K$3-$B$2)<30), 2,0) -> 0 | L14: =IF(OR(AND($F13<=L$3, $F14 >= L$3), AND($F14<L$3, WORKDAY($F14, 22,Holiday!$A$1:$A$30)>L$3)), 1, 0)+IF(AND((L$3-$B$2)>=0,(L$3-$B$2)<30), 2,0) -> 0 | M14: =IF(OR(AND($F13<=M$3, $F14 >= M$3), AND($F14<M$3, WORKDAY($F14, 22,Holiday!$A$1:$A$30)>M$3)), 1, 0)+IF(AND((M$3-$B$2)>=0,(M$3-$B$2)<30), 2,0) -> 1 | N14: =IF(OR(AND($F13<=N$3, $F14 >= N$3), AND($F14<N$3, WORKDAY($F14, 22,Holiday!$A$1:$A$30)>N$3)), 1, 0)+IF(AND((N$3-$B$2)>=0,(N$3-$B$2)<30), 2,0) -> 1 | ... AO14: =IF(OR(AND($F13<=AO$3, $F14 >= AO$3), AND($F14<AO$3, WORKDAY($F14, 22,Holiday!$A$1:$A$30)>AO$3)), 1, 0)+IF(AND((AO$3-$B$2)>=0,(AO$3-$B$2)<30), 2,0) -> 0
B15: Admin Tools/ Verify Phone List | C15: DEV 1 | D15: 10 | E15: =ROUNDUP(D15*(1+$D$2),0) -> 15 | F15: =WORKDAY(F14,E15,Holiday!A11:A40) -> 46283 | G15: =IF(OR(AND($F14<=G$3, $F15 >= G$3), AND($F15<G$3, WORKDAY($F15, 22,Holiday!$A$1:$A$30)>G$3)), 1, 0)+IF(AND((G$3-$B$2)>=0,(G$3-$B$2)<30), 2,0) -> 0 | H15: =IF(OR(AND($F14<=H$3, $F15 >= H$3), AND($F15<H$3, WORKDAY($F15, 22,Holiday!$A$1:$A$30)>H$3)), 1, 0)+IF(AND((H$3-$B$2)>=0,(H$3-$B$2)<30), 2,0) -> 0 | I15: =IF(OR(AND($F14<=I$3, $F15 >= I$3), AND($F15<I$3, WORKDAY($F15, 22,Holiday!$A$1:$A$30)>I$3)), 1, 0)+IF(AND((I$3-$B$2)>=0,(I$3-$B$2)<30), 2,0) -> 0 | J15: =IF(OR(AND($F14<=J$3, $F15 >= J$3), AND($F15<J$3, WORKDAY($F15, 22,Holiday!$A$1:$A$30)>J$3)), 1, 0)+IF(AND((J$3-$B$2)>=0,(J$3-$B$2)<30), 2,0) -> 0 | K15: =IF(OR(AND($F14<=K$3, $F15 >= K$3), AND($F15<K$3, WORKDAY($F15, 22,Holiday!$A$1:$A$30)>K$3)), 1, 0)+IF(AND((K$3-$B$2)>=0,(K$3-$B$2)<30), 2,0) -> 0 | L15: =IF(OR(AND($F14<=L$3, $F15 >= L$3), AND($F15<L$3, WORKDAY($F15, 22,Holiday!$A$1:$A$30)>L$3)), 1, 0)+IF(AND((L$3-$B$2)>=0,(L$3-$B$2)<30), 2,0) -> 0 | M15: =IF(OR(AND($F14<=M$3, $F15 >= M$3), AND($F15<M$3, WORKDAY($F15, 22,Holiday!$A$1:$A$30)>M$3)), 1, 0)+IF(AND((M$3-$B$2)>=0,(M$3-$B$2)<30), 2,0) -> 0 | N15: =IF(OR(AND($F14<=N$3, $F15 >= N$3), AND($F15<N$3, WORKDAY($F15, 22,Holiday!$A$1:$A$30)>N$3)), 1, 0)+IF(AND((N$3-$B$2)>=0,(N$3-$B$2)<30), 2,0) -> 1 | ... AO15: =IF(OR(AND($F14<=AO$3, $F15 >= AO$3), AND($F15<AO$3, WORKDAY($F15, 22,Holiday!$A$1:$A$30)>AO$3)), 1, 0)+IF(AND((AO$3-$B$2)>=0,(AO$3-$B$2)<30), 2,0) -> 0
B16: Admin Tools/Invalidate Follow-up trail | C16: DEV 1 | D16: 10 | E16: =ROUNDUP(D16*(1+$D$2),0) -> 15 | F16: =WORKDAY(F15,E16,Holiday!A12:A41) -> 46304 | G16: =IF(OR(AND($F15<=G$3, $F16 >= G$3), AND($F16<G$3, WORKDAY($F16, 22,Holiday!$A$1:$A$30)>G$3)), 1, 0)+IF(AND((G$3-$B$2)>=0,(G$3-$B$2)<30), 2,0) -> 0 | H16: =IF(OR(AND($F15<=H$3, $F16 >= H$3), AND($F16<H$3, WORKDAY($F16, 22,Holiday!$A$1:$A$30)>H$3)), 1, 0)+IF(AND((H$3-$B$2)>=0,(H$3-$B$2)<30), 2,0) -> 0 | I16: =IF(OR(AND($F15<=I$3, $F16 >= I$3), AND($F16<I$3, WORKDAY($F16, 22,Holiday!$A$1:$A$30)>I$3)), 1, 0)+IF(AND((I$3-$B$2)>=0,(I$3-$B$2)<30), 2,0) -> 0 | J16: =IF(OR(AND($F15<=J$3, $F16 >= J$3), AND($F16<J$3, WORKDAY($F16, 22,Holiday!$A$1:$A$30)>J$3)), 1, 0)+IF(AND((J$3-$B$2)>=0,(J$3-$B$2)<30), 2,0) -> 0 | K16: =IF(OR(AND($F15<=K$3, $F16 >= K$3), AND($F16<K$3, WORKDAY($F16, 22,Holiday!$A$1:$A$30)>K$3)), 1, 0)+IF(AND((K$3-$B$2)>=0,(K$3-$B$2)<30), 2,0) -> 0 | L16: =IF(OR(AND($F15<=L$3, $F16 >= L$3), AND($F16<L$3, WORKDAY($F16, 22,Holiday!$A$1:$A$30)>L$3)), 1, 0)+IF(AND((L$3-$B$2)>=0,(L$3-$B$2)<30), 2,0) -> 0 | M16: =IF(OR(AND($F15<=M$3, $F16 >= M$3), AND($F16<M$3, WORKDAY($F16, 22,Holiday!$A$1:$A$30)>M$3)), 1, 0)+IF(AND((M$3-$B$2)>=0,(M$3-$B$2)<30), 2,0) -> 0 | N16: =IF(OR(AND($F15<=N$3, $F16 >= N$3), AND($F16<N$3, WORKDAY($F16, 22,Holiday!$A$1:$A$30)>N$3)), 1, 0)+IF(AND((N$3-$B$2)>=0,(N$3-$B$2)<30), 2,0) -> 0 | ... AO16: =IF(OR(AND($F15<=AO$3, $F16 >= AO$3), AND($F16<AO$3, WORKDAY($F16, 22,Holiday!$A$1:$A$30)>AO$3)), 1, 0)+IF(AND((AO$3-$B$2)>=0,(AO$3-$B$2)<30), 2,0) -> 0
... B18: Correspondance | C18: DEV 1 | D18: 10 | E18: =ROUNDUP(D18*(1+$D$2),0) -> 15 | F18: =WORKDAY(F17,E18,Holiday!A14:A43) -> 46346 | G18: =IF(OR(AND($F17<=G$3, $F18 >= G$3), AND($F18<G$3, WORKDAY($F18, 22,Holiday!$A$1:$A$30)>G$3)), 1, 0)+IF(AND((G$3-$B$2)>=0,(G$3-$B$2)<30), 2,0) -> 0 | H18: =IF(OR(AND($F17<=H$3, $F18 >= H$3), AND($F18<H$3, WORKDAY($F18, 22,Holiday!$A$1:$A$30)>H$3)), 1, 0)+IF(AND((H$3-$B$2)>=0,(H$3-$B$2)<30), 2,0) -> 0 | I18: =IF(OR(AND($F17<=I$3, $F18 >= I$3), AND($F18<I$3, WORKDAY($F18, 22,Holiday!$A$1:$A$30)>I$3)), 1, 0)+IF(AND((I$3-$B$2)>=0,(I$3-$B$2)<30), 2,0) -> 0 | J18: =IF(OR(AND($F17<=J$3, $F18 >= J$3), AND($F18<J$3, WORKDAY($F18, 22,Holiday!$A$1:$A$30)>J$3)), 1, 0)+IF(AND((J$3-$B$2)>=0,(J$3-$B$2)<30), 2,0) -> 0 | K18: =IF(OR(AND($F17<=K$3, $F18 >= K$3), AND($F18<K$3, WORKDAY($F18, 22,Holiday!$A$1:$A$30)>K$3)), 1, 0)+IF(AND((K$3-$B$2)>=0,(K$3-$B$2)<30), 2,0) -> 0 | L18: =IF(OR(AND($F17<=L$3, $F18 >= L$3), AND($F18<L$3, WORKDAY($F18, 22,Holiday!$A$1:$A$30)>L$3)), 1, 0)+IF(AND((L$3-$B$2)>=0,(L$3-$B$2)<30), 2,0) -> 0 | M18: =IF(OR(AND($F17<=M$3, $F18 >= M$3), AND($F18<M$3, WORKDAY($F18, 22,Holiday!$A$1:$A$30)>M$3)), 1, 0)+IF(AND((M$3-$B$2)>=0,(M$3-$B$2)<30), 2,0) -> 0 | N18: =IF(OR(AND($F17<=N$3, $F18 >= N$3), AND($F18<N$3, WORKDAY($F18, 22,Holiday!$A$1:$A$30)>N$3)), 1, 0)+IF(AND((N$3-$B$2)>=0,(N$3-$B$2)<30), 2,0) -> 0 | ... AO18: =IF(OR(AND($F17<=AO$3, $F18 >= AO$3), AND($F18<AO$3, WORKDAY($F18, 22,Holiday!$A$1:$A$30)>AO$3)), 1, 0)+IF(AND((AO$3-$B$2)>=0,(AO$3-$B$2)<30), 2,0) -> 0
B19: Data Table / Bulk FollowUp Data | C19: DEV 2 | D19: 5 | E19: =ROUNDUP(D19*(1+$D$2),0) -> 8 | F19: =WORKDAY(F4,E19,Holiday!A15:A44) -> 46063 | G19: =IF(OR(AND($F18<=G$3, $F19 >= G$3), AND($F19<G$3, WORKDAY($F19, 22,Holiday!$A$1:$A$30)>G$3)), 1, 0)+IF(AND((G$3-$B$2)>=0,(G$3-$B$2)<30), 2,0) -> 0 | H19: =IF(OR(AND($F18<=H$3, $F19 >= H$3), AND($F19<H$3, WORKDAY($F19, 22,Holiday!$A$1:$A$30)>H$3)), 1, 0)+IF(AND((H$3-$B$2)>=0,(H$3-$B$2)<30), 2,0) -> 1 | I19: =IF(OR(AND($F18<=I$3, $F19 >= I$3), AND($F19<I$3, WORKDAY($F19, 22,Holiday!$A$1:$A$30)>I$3)), 1, 0)+IF(AND((I$3-$B$2)>=0,(I$3-$B$2)<30), 2,0) -> 0 | J19: =IF(OR(AND($F18<=J$3, $F19 >= J$3), AND($F19<J$3, WORKDAY($F19, 22,Holiday!$A$1:$A$30)>J$3)), 1, 0)+IF(AND((J$3-$B$2)>=0,(J$3-$B$2)<30), 2,0) -> 0 | K19: =IF(OR(AND($F18<=K$3, $F19 >= K$3), AND($F19<K$3, WORKDAY($F19, 22,Holiday!$A$1:$A$30)>K$3)), 1, 0)+IF(AND((K$3-$B$2)>=0,(K$3-$B$2)<30), 2,0) -> 0 | L19: =IF(OR(AND($F18<=L$3, $F19 >= L$3), AND($F19<L$3, WORKDAY($F19, 22,Holiday!$A$1:$A$30)>L$3)), 1, 0)+IF(AND((L$3-$B$2)>=0,(L$3-$B$2)<30), 2,0) -> 0 | M19: =IF(OR(AND($F18<=M$3, $F19 >= M$3), AND($F19<M$3, WORKDAY($F19, 22,Holiday!$A$1:$A$30)>M$3)), 1, 0)+IF(AND((M$3-$B$2)>=0,(M$3-$B$2)<30), 2,0) -> 0 | N19: =IF(OR(AND($F18<=N$3, $F19 >= N$3), AND($F19<N$3, WORKDAY($F19, 22,Holiday!$A$1:$A$30)>N$3)), 1, 0)+IF(AND((N$3-$B$2)>=0,(N$3-$B$2)<30), 2,0) -> 0 | ... AO19: =IF(OR(AND($F18<=AO$3, $F19 >= AO$3), AND($F19<AO$3, WORKDAY($F19, 22,Holiday!$A$1:$A$30)>AO$3)), 1, 0)+IF(AND((AO$3-$B$2)>=0,(AO$3-$B$2)<30), 2,0) -> 0
B20: Data Table/ BlackListPhoneNos | C20: DEV 2 | D20: 5 | E20: =ROUNDUP(D20*(1+$D$2),0) -> 8 | F20: =WORKDAY(F19,E20,Holiday!A16:A45) -> 46073 | G20: =IF(OR(AND($F19<=G$3, $F20 >= G$3), AND($F20<G$3, WORKDAY($F20, 22,Holiday!$A$1:$A$30)>G$3)), 1, 0)+IF(AND((G$3-$B$2)>=0,(G$3-$B$2)<30), 2,0) -> 0 | H20: =IF(OR(AND($F19<=H$3, $F20 >= H$3), AND($F20<H$3, WORKDAY($F20, 22,Holiday!$A$1:$A$30)>H$3)), 1, 0)+IF(AND((H$3-$B$2)>=0,(H$3-$B$2)<30), 2,0) -> 1 | I20: =IF(OR(AND($F19<=I$3, $F20 >= I$3), AND($F20<I$3, WORKDAY($F20, 22,Holiday!$A$1:$A$30)>I$3)), 1, 0)+IF(AND((I$3-$B$2)>=0,(I$3-$B$2)<30), 2,0) -> 0 | J20: =IF(OR(AND($F19<=J$3, $F20 >= J$3), AND($F20<J$3, WORKDAY($F20, 22,Holiday!$A$1:$A$30)>J$3)), 1, 0)+IF(AND((J$3-$B$2)>=0,(J$3-$B$2)<30), 2,0) -> 0 | K20: =IF(OR(AND($F19<=K$3, $F20 >= K$3), AND($F20<K$3, WORKDAY($F20, 22,Holiday!$A$1:$A$30)>K$3)), 1, 0)+IF(AND((K$3-$B$2)>=0,(K$3-$B$2)<30), 2,0) -> 0 | L20: =IF(OR(AND($F19<=L$3, $F20 >= L$3), AND($F20<L$3, WORKDAY($F20, 22,Holiday!$A$1:$A$30)>L$3)), 1, 0)+IF(AND((L$3-$B$2)>=0,(L$3-$B$2)<30), 2,0) -> 0 | M20: =IF(OR(AND($F19<=M$3, $F20 >= M$3), AND($F20<M$3, WORKDAY($F20, 22,Holiday!$A$1:$A$30)>M$3)), 1, 0)+IF(AND((M$3-$B$2)>=0,(M$3-$B$2)<30), 2,0) -> 0 | N20: =IF(OR(AND($F19<=N$3, $F20 >= N$3), AND($F20<N$3, WORKDAY($F20, 22,Holiday!$A$1:$A$30)>N$3)), 1, 0)+IF(AND((N$3-$B$2)>=0,(N$3-$B$2)<30), 2,0) -> 0 | ... AO20: =IF(OR(AND($F19<=AO$3, $F20 >= AO$3), AND($F20<AO$3, WORKDAY($F20, 22,Holiday!$A$1:$A$30)>AO$3)), 1, 0)+IF(AND((AO$3-$B$2)>=0,(AO$3-$B$2)<30), 2,0) -> 0
B21: Data Table/ Bulk Transfer | C21: DEV 2 | D21: 5 | E21: =ROUNDUP(D21*(1+$D$2),0) -> 8 | F21: =WORKDAY(F20,E21,Holiday!A17:A46) -> 46085 | G21: =IF(OR(AND($F20<=G$3, $F21 >= G$3), AND($F21<G$3, WORKDAY($F21, 22,Holiday!$A$1:$A$30)>G$3)), 1, 0)+IF(AND((G$3-$B$2)>=0,(G$3-$B$2)<30), 2,0) -> 0 | H21: =IF(OR(AND($F20<=H$3, $F21 >= H$3), AND($F21<H$3, WORKDAY($F21, 22,Holiday!$A$1:$A$30)>H$3)), 1, 0)+IF(AND((H$3-$B$2)>=0,(H$3-$B$2)<30), 2,0) -> 1 | I21: =IF(OR(AND($F20<=I$3, $F21 >= I$3), AND($F21<I$3, WORKDAY($F21, 22,Holiday!$A$1:$A$30)>I$3)), 1, 0)+IF(AND((I$3-$B$2)>=0,(I$3-$B$2)<30), 2,0) -> 0 | J21: =IF(OR(AND($F20<=J$3, $F21 >= J$3), AND($F21<J$3, WORKDAY($F21, 22,Holiday!$A$1:$A$30)>J$3)), 1, 0)+IF(AND((J$3-$B$2)>=0,(J$3-$B$2)<30), 2,0) -> 0 | K21: =IF(OR(AND($F20<=K$3, $F21 >= K$3), AND($F21<K$3, WORKDAY($F21, 22,Holiday!$A$1:$A$30)>K$3)), 1, 0)+IF(AND((K$3-$B$2)>=0,(K$3-$B$2)<30), 2,0) -> 0 | L21: =IF(OR(AND($F20<=L$3, $F21 >= L$3), AND($F21<L$3, WORKDAY($F21, 22,Holiday!$A$1:$A$30)>L$3)), 1, 0)+IF(AND((L$3-$B$2)>=0,(L$3-$B$2)<30), 2,0) -> 0 | M21: =IF(OR(AND($F20<=M$3, $F21 >= M$3), AND($F21<M$3, WORKDAY($F21, 22,Holiday!$A$1:$A$30)>M$3)), 1, 0)+IF(AND((M$3-$B$2)>=0,(M$3-$B$2)<30), 2,0) -> 0 | N21: =IF(OR(AND($F20<=N$3, $F21 >= N$3), AND($F21<N$3, WORKDAY($F21, 22,Holiday!$A$1:$A$30)>N$3)), 1, 0)+IF(AND((N$3-$B$2)>=0,(N$3-$B$2)<30), 2,0) -> 0 | ... AO21: =IF(OR(AND($F20<=AO$3, $F21 >= AO$3), AND($F21<AO$3, WORKDAY($F21, 22,Holiday!$A$1:$A$30)>AO$3)), 1, 0)+IF(AND((AO$3-$B$2)>=0,(AO$3-$B$2)<30), 2,0) -> 0
